SEED: 0
INIT_TIME: 0
FIN_TIME: 20000
ARRIVE_MIN: 5
ARRIVE_MAX: 8
QUIT_PROB: 20
CPU_MIN: 10
CPU_MAX: 25
DISK1_MIN: 10
DISK1_MAX: 20
DISK2_MIN: 15
DISK2_MAX: 25
Simulation starting at time: 0
Job #1 arrived at time: 0
Job #2 arrived at time: 6
Job #1 arrived at CPU at time: 15
Job #3 arrived at time: 15
Job #2 arrived at CPU at time: 25
Job #4 arrived at time: 25
Job #3 arrived at CPU at time: 33
Job #5 arrived at time: 33
Job #4 arrived at CPU at time: 40
Job #1 finished at CPU at time: 40
Job #2 finished at CPU at time: 40
Job #6 arrived at time: 40
Job #5 arrived at CPU at time: 50
Job #1 arrived at Disk2 at time: 50
Job #7 arrived at time: 50
Job #6 arrived at CPU at time: 68
Job #3 finished at CPU at time: 68
Job #8 arrived at time: 68
Job #7 arrived at CPU at time: 81
Job #3 finished at time: 81
Job #1 finished at Disk2 at time: 81
Job #5 finished at CPU at time: 81
Job #9 arrived at time: 81
Job #8 arrived at CPU at time: 89
Job #1 finished at time: 89
Job #2 arrived at Disk2 at time: 89
Job #5 arrived at Disk1 at time: 89
Job #4 finished at CPU at time: 89
Job #10 arrived at time: 89
Job #9 arrived at CPU at time: 106
Job #6 finished at CPU at time: 106
Job #11 arrived at time: 106
Job #10 arrived at CPU at time: 112
Job #6 finished at time: 112
Job #7 finished at CPU at time: 112
Job #8 finished at CPU at time: 112
Job #12 arrived at time: 112
Job #11 arrived at CPU at time: 127
Job #8 finished at time: 127
Job #2 finished at Disk2 at time: 127
Job #5 finished at Disk1 at time: 127
Job #13 arrived at time: 127
Job #12 arrived at CPU at time: 135
Job #2 finished at time: 135
Job #1 arrived at Disk2 at time: 135
Job #5 finished at time: 135
Job #5 arrived at Disk1 at time: 135
Job #14 arrived at time: 135
Job #13 arrived at CPU at time: 149
Job #10 finished at CPU at time: 149
Job #9 finished at CPU at time: 149
Job #12 finished at CPU at time: 149
Job #5 finished at Disk1 at time: 149
Job #15 arrived at time: 149
Job #14 arrived at CPU at time: 161
Job #9 finished at time: 161
Job #5 finished at time: 161
Job #4 arrived at Disk1 at time: 161
Job #16 arrived at time: 161
Job #15 arrived at CPU at time: 172
Job #11 finished at CPU at time: 172
Job #17 arrived at time: 172
Job #16 arrived at CPU at time: 185
Job #18 arrived at time: 185
Job #17 arrived at CPU at time: 202
Job #1 finished at Disk2 at time: 202
Job #13 finished at CPU at time: 202
Job #4 finished at Disk1 at time: 202
Job #15 finished at CPU at time: 202
Job #19 arrived at time: 202
Job #18 arrived at CPU at time: 216
Job #1 finished at time: 216
Job #2 arrived at Disk2 at time: 216
Job #13 finished at time: 216
Job #4 finished at time: 216
Job #5 arrived at Disk1 at time: 216
Job #14 finished at CPU at time: 216
Job #20 arrived at time: 216
Job #19 arrived at CPU at time: 230
Job #16 finished at CPU at time: 230
Job #21 arrived at time: 230
Job #20 arrived at CPU at time: 240
Job #17 finished at CPU at time: 240
Job #5 finished at Disk1 at time: 240
Job #18 finished at CPU at time: 240
Job #22 arrived at time: 240
Job #21 arrived at CPU at time: 256
Job #17 finished at time: 256
Job #5 finished at time: 256
Job #10 arrived at Disk1 at time: 256
Job #18 finished at time: 256
Job #2 finished at Disk2 at time: 256
Job #19 finished at CPU at time: 256
Job #23 arrived at time: 256
Job #22 arrived at CPU at time: 264
Job #2 finished at time: 264
Job #7 arrived at Disk2 at time: 264
Job #24 arrived at time: 264
Job #23 arrived at CPU at time: 279
Job #20 finished at CPU at time: 279
Job #21 finished at CPU at time: 279
Job #25 arrived at time: 279
Job #24 arrived at CPU at time: 293
Job #10 finished at Disk1 at time: 293
Job #22 finished at CPU at time: 293
Job #26 arrived at time: 293
Job #25 arrived at CPU at time: 308
Job #10 finished at time: 308
Job #4 arrived at Disk1 at time: 308
Job #7 finished at Disk2 at time: 308
Job #23 finished at CPU at time: 308
Job #27 arrived at time: 308
Job #26 arrived at CPU at time: 317
Job #7 finished at time: 317
Job #1 arrived at Disk2 at time: 317
Job #24 finished at CPU at time: 317
Job #28 arrived at time: 317
Job #27 arrived at CPU at time: 323
Job #4 finished at Disk1 at time: 323
Job #29 arrived at time: 323
Job #28 arrived at CPU at time: 332
Job #4 finished at time: 332
Job #11 arrived at Disk1 at time: 332
Job #30 arrived at time: 332
Job #29 arrived at CPU at time: 344
Job #25 finished at CPU at time: 344
Job #26 finished at CPU at time: 344
Job #11 finished at Disk1 at time: 344
Job #31 arrived at time: 344
Job #30 arrived at CPU at time: 353
Job #11 finished at time: 353
Job #5 arrived at Disk1 at time: 353
Job #28 finished at CPU at time: 353
Job #32 arrived at time: 353
Job #31 arrived at CPU at time: 368
Job #1 finished at Disk2 at time: 368
Job #27 finished at CPU at time: 368
Job #33 arrived at time: 368
Job #32 arrived at CPU at time: 378
Job #1 finished at time: 378
Job #12 arrived at Disk2 at time: 378
Job #30 finished at CPU at time: 378
Job #34 arrived at time: 378
Job #33 arrived at CPU at time: 383
Job #29 finished at CPU at time: 383
Job #5 finished at Disk1 at time: 383
Job #35 arrived at time: 383
Job #34 arrived at CPU at time: 399
Job #5 finished at time: 399
Job #14 arrived at Disk1 at time: 399
Job #31 finished at CPU at time: 399
Job #32 finished at CPU at time: 399
Job #36 arrived at time: 399
Job #35 arrived at CPU at time: 417
Job #33 finished at CPU at time: 417
Job #14 finished at Disk1 at time: 417
Job #37 arrived at time: 417
Job #36 arrived at CPU at time: 434
Job #14 finished at time: 434
Job #10 arrived at Disk1 at time: 434
Job #34 finished at CPU at time: 434
Job #12 finished at Disk2 at time: 434
Job #38 arrived at time: 434
Job #37 arrived at CPU at time: 442
Job #12 finished at time: 442
Job #15 arrived at Disk2 at time: 442
Job #39 arrived at time: 442
Job #38 arrived at CPU at time: 452
Job #40 arrived at time: 452
Job #39 arrived at CPU at time: 462
Job #35 finished at CPU at time: 462
Job #41 arrived at time: 462
Job #40 arrived at CPU at time: 472
Job #37 finished at CPU at time: 472
Job #10 finished at Disk1 at time: 472
Job #38 finished at CPU at time: 472
Job #42 arrived at time: 472
Job #41 arrived at CPU at time: 485
Job #10 finished at time: 485
Job #20 arrived at Disk1 at time: 485
Job #39 finished at CPU at time: 485
Job #36 finished at CPU at time: 485
Job #15 finished at Disk2 at time: 485
Job #43 arrived at time: 485
Job #42 arrived at CPU at time: 493
Job #15 finished at time: 493
Job #2 arrived at Disk2 at time: 493
Job #44 arrived at time: 493
Job #43 arrived at CPU at time: 501
Job #45 arrived at time: 501
Job #44 arrived at CPU at time: 516
Job #40 finished at CPU at time: 516
Job #41 finished at CPU at time: 516
Job #20 finished at Disk1 at time: 516
Job #2 finished at Disk2 at time: 516
Job #46 arrived at time: 516
Job #45 arrived at CPU at time: 531
Job #40 finished at time: 531
Job #20 finished at time: 531
Job #21 arrived at Disk1 at time: 531
Job #2 finished at time: 531
Job #16 arrived at Disk2 at time: 531
Job #43 finished at CPU at time: 531
Job #42 finished at CPU at time: 531
Job #44 finished at CPU at time: 531
Job #47 arrived at time: 531
Job #46 arrived at CPU at time: 541
Job #43 finished at time: 541
Job #48 arrived at time: 541
Job #47 arrived at CPU at time: 553
Job #21 finished at Disk1 at time: 553
Job #49 arrived at time: 553
Job #48 arrived at CPU at time: 566
Job #21 finished at time: 566
Job #22 arrived at Disk1 at time: 566
Job #16 finished at Disk2 at time: 566
Job #45 finished at CPU at time: 566
Job #46 finished at CPU at time: 566
Job #50 arrived at time: 566
Job #49 arrived at CPU at time: 578
Job #16 finished at time: 578
Job #19 arrived at Disk2 at time: 578
Job #47 finished at CPU at time: 578
Job #51 arrived at time: 578
Job #50 arrived at CPU at time: 587
Job #48 finished at CPU at time: 587
Job #22 finished at Disk1 at time: 587
Job #52 arrived at time: 587
Job #51 arrived at CPU at time: 600
Job #48 finished at time: 600
Job #22 finished at time: 600
Job #4 arrived at Disk1 at time: 600
Job #49 finished at CPU at time: 600
Job #53 arrived at time: 600
Job #52 arrived at CPU at time: 606
Job #54 arrived at time: 606
Job #53 arrived at CPU at time: 611
Job #55 arrived at time: 611
Job #54 arrived at CPU at time: 627
Job #4 finished at Disk1 at time: 627
Job #19 finished at Disk2 at time: 627
Job #51 finished at CPU at time: 627
Job #53 finished at CPU at time: 627
Job #56 arrived at time: 627
Job #55 arrived at CPU at time: 641
Job #4 finished at time: 641
Job #11 arrived at Disk1 at time: 641
Job #19 finished at time: 641
Job #7 arrived at Disk2 at time: 641
Job #50 finished at CPU at time: 641
Job #57 arrived at time: 641
Job #56 arrived at CPU at time: 653
Job #52 finished at CPU at time: 653
Job #11 finished at Disk1 at time: 653
Job #58 arrived at time: 653
Job #57 arrived at CPU at time: 667
Job #11 finished at time: 667
Job #25 arrived at Disk1 at time: 667
Job #54 finished at CPU at time: 667
Job #56 finished at CPU at time: 667
Job #59 arrived at time: 667
Job #58 arrived at CPU at time: 676
Job #60 arrived at time: 676
Job #59 arrived at CPU at time: 687
Job #25 finished at Disk1 at time: 687
Job #55 finished at CPU at time: 687
Job #61 arrived at time: 687
Job #60 arrived at CPU at time: 701
Job #25 finished at time: 701
Job #5 arrived at Disk1 at time: 701
Job #7 finished at Disk2 at time: 701
Job #57 finished at CPU at time: 701
Job #58 finished at CPU at time: 701
Job #62 arrived at time: 701
Job #61 arrived at CPU at time: 710
Job #7 finished at time: 710
Job #23 arrived at Disk2 at time: 710
Job #63 arrived at time: 710
Job #62 arrived at CPU at time: 719
Job #64 arrived at time: 719
Job #63 arrived at CPU at time: 729
Job #59 finished at CPU at time: 729
Job #60 finished at CPU at time: 729
Job #23 finished at Disk2 at time: 729
Job #5 finished at Disk1 at time: 729
Job #65 arrived at time: 729
Job #64 arrived at CPU at time: 741
Job #23 finished at time: 741
Job #1 arrived at Disk2 at time: 741
Job #5 finished at time: 741
Job #28 arrived at Disk1 at time: 741
Job #66 arrived at time: 741
Job #65 arrived at CPU at time: 759
Job #61 finished at CPU at time: 759
Job #64 finished at CPU at time: 759
Job #67 arrived at time: 759
Job #66 arrived at CPU at time: 770
Job #61 finished at time: 770
Job #62 finished at CPU at time: 770
Job #63 finished at CPU at time: 770
Job #68 arrived at time: 770
Job #67 arrived at CPU at time: 775
Job #28 finished at Disk1 at time: 775
Job #69 arrived at time: 775
Job #68 arrived at CPU at time: 792
Job #28 finished at time: 792
Job #30 arrived at Disk1 at time: 792
Job #1 finished at Disk2 at time: 792
Job #70 arrived at time: 792
Job #69 arrived at CPU at time: 802
Job #1 finished at time: 802
Job #24 arrived at Disk2 at time: 802
Job #65 finished at CPU at time: 802
Job #71 arrived at time: 802
Job #70 arrived at CPU at time: 811
Job #67 finished at CPU at time: 811
Job #68 finished at CPU at time: 811
Job #66 finished at CPU at time: 811
Job #72 arrived at time: 811
Job #71 arrived at CPU at time: 821
Job #67 finished at time: 821
Job #69 finished at CPU at time: 821
Job #30 finished at Disk1 at time: 821
Job #73 arrived at time: 821
Job #72 arrived at CPU at time: 838
Job #30 finished at time: 838
Job #14 arrived at Disk1 at time: 838
Job #24 finished at Disk2 at time: 838
Job #74 arrived at time: 838
Job #73 arrived at CPU at time: 847
Job #24 finished at time: 847
Job #26 arrived at Disk2 at time: 847
Job #70 finished at CPU at time: 847
Job #75 arrived at time: 847
Job #74 arrived at CPU at time: 854
Job #70 finished at time: 854
Job #71 finished at CPU at time: 854
Job #76 arrived at time: 854
Job #75 arrived at CPU at time: 867
Job #14 finished at Disk1 at time: 867
Job #77 arrived at time: 867
Job #76 arrived at CPU at time: 874
Job #14 finished at time: 874
Job #31 arrived at Disk1 at time: 874
Job #72 finished at CPU at time: 874
Job #78 arrived at time: 874
Job #77 arrived at CPU at time: 891
Job #75 finished at CPU at time: 891
Job #73 finished at CPU at time: 891
Job #26 finished at Disk2 at time: 891
Job #79 arrived at time: 891
Job #78 arrived at CPU at time: 896
Job #75 finished at time: 896
Job #26 finished at time: 896
Job #27 arrived at Disk2 at time: 896
Job #80 arrived at time: 896
Job #79 arrived at CPU at time: 903
Job #74 finished at CPU at time: 903
Job #31 finished at Disk1 at time: 903
Job #81 arrived at time: 903
Job #80 arrived at CPU at time: 912
Job #74 finished at time: 912
Job #31 finished at time: 912
Job #33 arrived at Disk1 at time: 912
Job #82 arrived at time: 912
Job #81 arrived at CPU at time: 927
Job #79 finished at CPU at time: 927
Job #76 finished at CPU at time: 927
Job #27 finished at Disk2 at time: 927
Job #83 arrived at time: 927
Job #82 arrived at CPU at time: 941
Job #27 finished at time: 941
Job #12 arrived at Disk2 at time: 941
Job #77 finished at CPU at time: 941
Job #78 finished at CPU at time: 941
Job #84 arrived at time: 941
Job #83 arrived at CPU at time: 956
Job #78 finished at time: 956
Job #33 finished at Disk1 at time: 956
Job #80 finished at CPU at time: 956
Job #85 arrived at time: 956
Job #84 arrived at CPU at time: 966
Job #33 finished at time: 966
Job #10 arrived at Disk1 at time: 966
Job #81 finished at CPU at time: 966
Job #82 finished at CPU at time: 966
Job #86 arrived at time: 966
Job #85 arrived at CPU at time: 978
Job #12 finished at Disk2 at time: 978
Job #83 finished at CPU at time: 978
Job #10 finished at Disk1 at time: 978
Job #87 arrived at time: 978
Job #86 arrived at CPU at time: 992
Job #12 finished at time: 992
Job #29 arrived at Disk2 at time: 992
Job #10 finished at time: 992
Job #35 arrived at Disk1 at time: 992
Job #84 finished at CPU at time: 992
Job #85 finished at CPU at time: 992
Job #88 arrived at time: 992
Job #87 arrived at CPU at time: 1001
Job #89 arrived at time: 1001
Job #88 arrived at CPU at time: 1008
Job #86 finished at CPU at time: 1008
Job #90 arrived at time: 1008
Job #89 arrived at CPU at time: 1024
Job #87 finished at CPU at time: 1024
Job #29 finished at Disk2 at time: 1024
Job #91 arrived at time: 1024
Job #90 arrived at CPU at time: 1029
Job #87 finished at time: 1029
Job #29 finished at time: 1029
Job #32 arrived at Disk2 at time: 1029
Job #35 finished at Disk1 at time: 1029
Job #92 arrived at time: 1029
Job #91 arrived at CPU at time: 1042
Job #35 finished at time: 1042
Job #38 arrived at Disk1 at time: 1042
Job #88 finished at CPU at time: 1042
Job #93 arrived at time: 1042
Job #92 arrived at CPU at time: 1059
Job #89 finished at CPU at time: 1059
Job #94 arrived at time: 1059
Job #93 arrived at CPU at time: 1065
Job #89 finished at time: 1065
Job #32 finished at Disk2 at time: 1065
Job #90 finished at CPU at time: 1065
Job #95 arrived at time: 1065
Job #94 arrived at CPU at time: 1083
Job #32 finished at time: 1083
Job #34 arrived at Disk2 at time: 1083
Job #90 finished at time: 1083
Job #38 finished at Disk1 at time: 1083
Job #91 finished at CPU at time: 1083
Job #96 arrived at time: 1083
Job #95 arrived at CPU at time: 1101
Job #38 finished at time: 1101
Job #20 arrived at Disk1 at time: 1101
Job #92 finished at CPU at time: 1101
Job #97 arrived at time: 1101
Job #96 arrived at CPU at time: 1115
Job #93 finished at CPU at time: 1115
Job #94 finished at CPU at time: 1115
Job #34 finished at Disk2 at time: 1115
Job #98 arrived at time: 1115
Job #97 arrived at CPU at time: 1123
Job #34 finished at time: 1123
Job #15 arrived at Disk2 at time: 1123
Job #99 arrived at time: 1123
Job #98 arrived at CPU at time: 1128
Job #100 arrived at time: 1128
Job #99 arrived at CPU at time: 1133
Job #20 finished at Disk1 at time: 1133
Job #96 finished at CPU at time: 1133
Job #101 arrived at time: 1133
Job #100 arrived at CPU at time: 1140
Job #20 finished at time: 1140
Job #36 arrived at Disk1 at time: 1140
Job #102 arrived at time: 1140
Job #101 arrived at CPU at time: 1154
Job #95 finished at CPU at time: 1154
Job #99 finished at CPU at time: 1154
Job #98 finished at CPU at time: 1154
Job #103 arrived at time: 1154
Job #102 arrived at CPU at time: 1169
Job #100 finished at CPU at time: 1169
Job #97 finished at CPU at time: 1169
Job #104 arrived at time: 1169
Job #103 arrived at CPU at time: 1176
Job #100 finished at time: 1176
Job #97 finished at time: 1176
Job #101 finished at CPU at time: 1176
Job #15 finished at Disk2 at time: 1176
Job #105 arrived at time: 1176
Job #104 arrived at CPU at time: 1183
Job #15 finished at time: 1183
Job #37 arrived at Disk2 at time: 1183
Job #36 finished at Disk1 at time: 1183
Job #106 arrived at time: 1183
Job #105 arrived at CPU at time: 1190
Job #36 finished at time: 1190
Job #21 arrived at Disk1 at time: 1190
Job #107 arrived at time: 1190
Job #106 arrived at CPU at time: 1199
Job #103 finished at CPU at time: 1199
Job #104 finished at CPU at time: 1199
Job #108 arrived at time: 1199
Job #107 arrived at CPU at time: 1208
Job #103 finished at time: 1208
Job #104 finished at time: 1208
Job #105 finished at CPU at time: 1208
Job #21 finished at Disk1 at time: 1208
Job #102 finished at CPU at time: 1208
Job #109 arrived at time: 1208
Job #108 arrived at CPU at time: 1221
Job #21 finished at time: 1221
Job #42 arrived at Disk1 at time: 1221
Job #110 arrived at time: 1221
Job #109 arrived at CPU at time: 1227
Job #106 finished at CPU at time: 1227
Job #111 arrived at time: 1227
Job #110 arrived at CPU at time: 1241
Job #106 finished at time: 1241
Job #107 finished at CPU at time: 1241
Job #37 finished at Disk2 at time: 1241
Job #112 arrived at time: 1241
Job #111 arrived at CPU at time: 1257
Job #37 finished at time: 1257
Job #39 arrived at Disk2 at time: 1257
Job #109 finished at CPU at time: 1257
Job #113 arrived at time: 1257
Job #112 arrived at CPU at time: 1265
Job #42 finished at Disk1 at time: 1265
Job #114 arrived at time: 1265
Job #113 arrived at CPU at time: 1276
Job #42 finished at time: 1276
Job #22 arrived at Disk1 at time: 1276
Job #108 finished at CPU at time: 1276
Job #39 finished at Disk2 at time: 1276
Job #115 arrived at time: 1276
Job #114 arrived at CPU at time: 1293
Job #39 finished at time: 1293
Job #2 arrived at Disk2 at time: 1293
Job #110 finished at CPU at time: 1293
Job #111 finished at CPU at time: 1293
Job #113 finished at CPU at time: 1293
Job #116 arrived at time: 1293
Job #115 arrived at CPU at time: 1302
Job #22 finished at Disk1 at time: 1302
Job #117 arrived at time: 1302
Job #116 arrived at CPU at time: 1313
Job #22 finished at time: 1313
Job #46 arrived at Disk1 at time: 1313
Job #112 finished at CPU at time: 1313
Job #118 arrived at time: 1313
Job #117 arrived at CPU at time: 1326
Job #112 finished at time: 1326
Job #114 finished at CPU at time: 1326
Job #46 finished at Disk1 at time: 1326
Job #119 arrived at time: 1326
Job #118 arrived at CPU at time: 1339
Job #46 finished at time: 1339
Job #47 arrived at Disk1 at time: 1339
Job #116 finished at CPU at time: 1339
Job #115 finished at CPU at time: 1339
Job #120 arrived at time: 1339
Job #119 arrived at CPU at time: 1355
Job #116 finished at time: 1355
Job #2 finished at Disk2 at time: 1355
Job #121 arrived at time: 1355
Job #120 arrived at CPU at time: 1367
Job #2 finished at time: 1367
Job #41 arrived at Disk2 at time: 1367
Job #117 finished at CPU at time: 1367
Job #118 finished at CPU at time: 1367
Job #119 finished at CPU at time: 1367
Job #122 arrived at time: 1367
Job #121 arrived at CPU at time: 1374
Job #123 arrived at time: 1374
Job #122 arrived at CPU at time: 1391
Job #47 finished at Disk1 at time: 1391
Job #120 finished at CPU at time: 1391
Job #41 finished at Disk2 at time: 1391
Job #124 arrived at time: 1391
Job #123 arrived at CPU at time: 1407
Job #47 finished at time: 1407
Job #4 arrived at Disk1 at time: 1407
Job #41 finished at time: 1407
Job #16 arrived at Disk2 at time: 1407
Job #125 arrived at time: 1407
Job #124 arrived at CPU at time: 1421
Job #121 finished at CPU at time: 1421
Job #126 arrived at time: 1421
Job #125 arrived at CPU at time: 1433
Job #16 finished at Disk2 at time: 1433
Job #122 finished at CPU at time: 1433
Job #127 arrived at time: 1433
Job #126 arrived at CPU at time: 1439
Job #16 finished at time: 1439
Job #44 arrived at Disk2 at time: 1439
Job #122 finished at time: 1439
Job #128 arrived at time: 1439
Job #127 arrived at CPU at time: 1451
Job #4 finished at Disk1 at time: 1451
Job #123 finished at CPU at time: 1451
Job #124 finished at CPU at time: 1451
Job #125 finished at CPU at time: 1451
Job #129 arrived at time: 1451
Job #128 arrived at CPU at time: 1462
Job #4 finished at time: 1462
Job #51 arrived at Disk1 at time: 1462
Job #125 finished at time: 1462
Job #126 finished at CPU at time: 1462
Job #44 finished at Disk2 at time: 1462
Job #130 arrived at time: 1462
Job #129 arrived at CPU at time: 1473
Job #44 finished at time: 1473
Job #45 arrived at Disk2 at time: 1473
Job #131 arrived at time: 1473
Job #130 arrived at CPU at time: 1484
Job #127 finished at CPU at time: 1484
Job #51 finished at Disk1 at time: 1484
Job #132 arrived at time: 1484
Job #131 arrived at CPU at time: 1491
Job #51 finished at time: 1491
Job #11 arrived at Disk1 at time: 1491
Job #45 finished at Disk2 at time: 1491
Job #129 finished at CPU at time: 1491
Job #133 arrived at time: 1491
Job #132 arrived at CPU at time: 1501
Job #45 finished at time: 1501
Job #19 arrived at Disk2 at time: 1501
Job #128 finished at CPU at time: 1501
Job #134 arrived at time: 1501
Job #133 arrived at CPU at time: 1509
Job #11 finished at Disk1 at time: 1509
Job #135 arrived at time: 1509
Job #134 arrived at CPU at time: 1519
Job #11 finished at time: 1519
Job #50 arrived at Disk1 at time: 1519
Job #136 arrived at time: 1519
Job #135 arrived at CPU at time: 1529
Job #130 finished at CPU at time: 1529
Job #131 finished at CPU at time: 1529
Job #137 arrived at time: 1529
Job #136 arrived at CPU at time: 1543
Job #133 finished at CPU at time: 1543
Job #138 arrived at time: 1543
Job #137 arrived at CPU at time: 1557
Job #132 finished at CPU at time: 1557
Job #19 finished at Disk2 at time: 1557
Job #50 finished at Disk1 at time: 1557
Job #139 arrived at time: 1557
Job #138 arrived at CPU at time: 1565
Job #132 finished at time: 1565
Job #19 finished at time: 1565
Job #49 arrived at Disk2 at time: 1565
Job #50 finished at time: 1565
Job #25 arrived at Disk1 at time: 1565
Job #135 finished at CPU at time: 1565
Job #134 finished at CPU at time: 1565
Job #140 arrived at time: 1565
Job #139 arrived at CPU at time: 1575
Job #135 finished at time: 1575
Job #136 finished at CPU at time: 1575
Job #141 arrived at time: 1575
Job #140 arrived at CPU at time: 1585
Job #137 finished at CPU at time: 1585
Job #142 arrived at time: 1585
Job #141 arrived at CPU at time: 1599
Job #137 finished at time: 1599
Job #138 finished at CPU at time: 1599
Job #49 finished at Disk2 at time: 1599
Job #25 finished at Disk1 at time: 1599
Job #143 arrived at time: 1599
Job #142 arrived at CPU at time: 1611
Job #138 finished at time: 1611
Job #49 finished at time: 1611
Job #53 arrived at Disk2 at time: 1611
Job #25 finished at time: 1611
Job #54 arrived at Disk1 at time: 1611
Job #144 arrived at time: 1611
Job #143 arrived at CPU at time: 1618
Job #140 finished at CPU at time: 1618
Job #139 finished at CPU at time: 1618
Job #145 arrived at time: 1618
Job #144 arrived at CPU at time: 1626
Job #141 finished at CPU at time: 1626
Job #146 arrived at time: 1626
Job #145 arrived at CPU at time: 1638
Job #142 finished at CPU at time: 1638
Job #54 finished at Disk1 at time: 1638
Job #147 arrived at time: 1638
Job #146 arrived at CPU at time: 1656
Job #142 finished at time: 1656
Job #54 finished at time: 1656
Job #55 arrived at Disk1 at time: 1656
Job #144 finished at CPU at time: 1656
Job #148 arrived at time: 1656
Job #147 arrived at CPU at time: 1674
Job #143 finished at CPU at time: 1674
Job #53 finished at Disk2 at time: 1674
Job #145 finished at CPU at time: 1674
Job #55 finished at Disk1 at time: 1674
Job #149 arrived at time: 1674
Job #148 arrived at CPU at time: 1682
Job #53 finished at time: 1682
Job #7 arrived at Disk2 at time: 1682
Job #55 finished at time: 1682
Job #5 arrived at Disk1 at time: 1682
Job #150 arrived at time: 1682
Job #149 arrived at CPU at time: 1699
Job #147 finished at CPU at time: 1699
Job #146 finished at CPU at time: 1699
Job #5 finished at Disk1 at time: 1699
Job #148 finished at CPU at time: 1699
Job #151 arrived at time: 1699
Job #150 arrived at CPU at time: 1711
Job #147 finished at time: 1711
Job #5 finished at time: 1711
Job #59 arrived at Disk1 at time: 1711
Job #7 finished at Disk2 at time: 1711
Job #152 arrived at time: 1711
Job #151 arrived at CPU at time: 1718
Job #7 finished at time: 1718
Job #52 arrived at Disk2 at time: 1718
Job #153 arrived at time: 1718
Job #152 arrived at CPU at time: 1725
Job #59 finished at Disk1 at time: 1725
Job #154 arrived at time: 1725
Job #153 arrived at CPU at time: 1734
Job #59 finished at time: 1734
Job #60 arrived at Disk1 at time: 1734
Job #151 finished at CPU at time: 1734
Job #155 arrived at time: 1734
Job #154 arrived at CPU at time: 1739
Job #150 finished at CPU at time: 1739
Job #149 finished at CPU at time: 1739
Job #156 arrived at time: 1739
Job #155 arrived at CPU at time: 1757
Job #152 finished at CPU at time: 1757
Job #52 finished at Disk2 at time: 1757
Job #157 arrived at time: 1757
Job #156 arrived at CPU at time: 1771
Job #52 finished at time: 1771
Job #56 arrived at Disk2 at time: 1771
Job #154 finished at CPU at time: 1771
Job #153 finished at CPU at time: 1771
Job #158 arrived at time: 1771
Job #157 arrived at CPU at time: 1786
Job #154 finished at time: 1786
Job #153 finished at time: 1786
Job #60 finished at Disk1 at time: 1786
Job #155 finished at CPU at time: 1786
Job #159 arrived at time: 1786
Job #158 arrived at CPU at time: 1797
Job #60 finished at time: 1797
Job #28 arrived at Disk1 at time: 1797
Job #155 finished at time: 1797
Job #160 arrived at time: 1797
Job #159 arrived at CPU at time: 1814
Job #157 finished at CPU at time: 1814
Job #56 finished at Disk2 at time: 1814
Job #156 finished at CPU at time: 1814
Job #158 finished at CPU at time: 1814
Job #28 finished at Disk1 at time: 1814
Job #161 arrived at time: 1814
Job #160 arrived at CPU at time: 1832
Job #56 finished at time: 1832
Job #57 arrived at Disk2 at time: 1832
Job #28 finished at time: 1832
Job #62 arrived at Disk1 at time: 1832
Job #162 arrived at time: 1832
Job #161 arrived at CPU at time: 1841
Job #163 arrived at time: 1841
Job #162 arrived at CPU at time: 1858
Job #159 finished at CPU at time: 1858
Job #57 finished at Disk2 at time: 1858
Job #164 arrived at time: 1858
Job #163 arrived at CPU at time: 1865
Job #57 finished at time: 1865
Job #58 arrived at Disk2 at time: 1865
Job #165 arrived at time: 1865
Job #164 arrived at CPU at time: 1870
Job #62 finished at Disk1 at time: 1870
Job #166 arrived at time: 1870
Job #165 arrived at CPU at time: 1888
Job #62 finished at time: 1888
Job #30 arrived at Disk1 at time: 1888
Job #160 finished at CPU at time: 1888
Job #164 finished at CPU at time: 1888
Job #163 finished at CPU at time: 1888
Job #161 finished at CPU at time: 1888
Job #167 arrived at time: 1888
Job #166 arrived at CPU at time: 1898
Job #160 finished at time: 1898
Job #161 finished at time: 1898
Job #168 arrived at time: 1898
Job #167 arrived at CPU at time: 1914
Job #162 finished at CPU at time: 1914
Job #30 finished at Disk1 at time: 1914
Job #169 arrived at time: 1914
Job #168 arrived at CPU at time: 1928
Job #30 finished at time: 1928
Job #65 arrived at Disk1 at time: 1928
Job #58 finished at Disk2 at time: 1928
Job #166 finished at CPU at time: 1928
Job #170 arrived at time: 1928
Job #169 arrived at CPU at time: 1939
Job #58 finished at time: 1939
Job #23 arrived at Disk2 at time: 1939
Job #167 finished at CPU at time: 1939
Job #165 finished at CPU at time: 1939
Job #171 arrived at time: 1939
Job #170 arrived at CPU at time: 1946
Job #172 arrived at time: 1946
Job #171 arrived at CPU at time: 1962
Job #65 finished at Disk1 at time: 1962
Job #173 arrived at time: 1962
Job #172 arrived at CPU at time: 1977
Job #65 finished at time: 1977
Job #66 arrived at Disk1 at time: 1977
Job #168 finished at CPU at time: 1977
Job #23 finished at Disk2 at time: 1977
Job #169 finished at CPU at time: 1977
Job #174 arrived at time: 1977
Job #173 arrived at CPU at time: 1984
Job #168 finished at time: 1984
Job #23 finished at time: 1984
Job #1 arrived at Disk2 at time: 1984
Job #171 finished at CPU at time: 1984
Job #175 arrived at time: 1984
Job #174 arrived at CPU at time: 2002
Job #170 finished at CPU at time: 2002
Job #176 arrived at time: 2002
Job #175 arrived at CPU at time: 2011
Job #177 arrived at time: 2011
Job #176 arrived at CPU at time: 2025
Job #66 finished at Disk1 at time: 2025
Job #172 finished at CPU at time: 2025
Job #174 finished at CPU at time: 2025
Job #1 finished at Disk2 at time: 2025
Job #178 arrived at time: 2025
Job #177 arrived at CPU at time: 2036
Job #66 finished at time: 2036
Job #14 arrived at Disk1 at time: 2036
Job #1 finished at time: 2036
Job #64 arrived at Disk2 at time: 2036
Job #173 finished at CPU at time: 2036
Job #175 finished at CPU at time: 2036
Job #179 arrived at time: 2036
Job #178 arrived at CPU at time: 2054
Job #180 arrived at time: 2054
Job #179 arrived at CPU at time: 2063
Job #14 finished at Disk1 at time: 2063
Job #181 arrived at time: 2063
Job #180 arrived at CPU at time: 2075
Job #14 finished at time: 2075
Job #71 arrived at Disk1 at time: 2075
Job #64 finished at Disk2 at time: 2075
Job #176 finished at CPU at time: 2075
Job #177 finished at CPU at time: 2075
Job #182 arrived at time: 2075
Job #181 arrived at CPU at time: 2080
Job #64 finished at time: 2080
Job #63 arrived at Disk2 at time: 2080
Job #183 arrived at time: 2080
Job #182 arrived at CPU at time: 2087
Job #184 arrived at time: 2087
Job #183 arrived at CPU at time: 2101
Job #71 finished at Disk1 at time: 2101
Job #180 finished at CPU at time: 2101
Job #178 finished at CPU at time: 2101
Job #63 finished at Disk2 at time: 2101
Job #185 arrived at time: 2101
Job #184 arrived at CPU at time: 2109
Job #71 finished at time: 2109
Job #31 arrived at Disk1 at time: 2109
Job #63 finished at time: 2109
Job #24 arrived at Disk2 at time: 2109
Job #179 finished at CPU at time: 2109
Job #181 finished at CPU at time: 2109
Job #186 arrived at time: 2109
Job #185 arrived at CPU at time: 2118
Job #181 finished at time: 2118
Job #182 finished at CPU at time: 2118
Job #187 arrived at time: 2118
Job #186 arrived at CPU at time: 2133
Job #183 finished at CPU at time: 2133
Job #188 arrived at time: 2133
Job #187 arrived at CPU at time: 2139
Job #31 finished at Disk1 at time: 2139
Job #185 finished at CPU at time: 2139
Job #189 arrived at time: 2139
Job #188 arrived at CPU at time: 2148
Job #31 finished at time: 2148
Job #73 arrived at Disk1 at time: 2148
Job #184 finished at CPU at time: 2148
Job #190 arrived at time: 2148
Job #189 arrived at CPU at time: 2164
Job #187 finished at CPU at time: 2164
Job #24 finished at Disk2 at time: 2164
Job #188 finished at CPU at time: 2164
Job #186 finished at CPU at time: 2164
Job #191 arrived at time: 2164
Job #190 arrived at CPU at time: 2170
Job #187 finished at time: 2170
Job #24 finished at time: 2170
Job #68 arrived at Disk2 at time: 2170
Job #73 finished at Disk1 at time: 2170
Job #192 arrived at time: 2170
Job #191 arrived at CPU at time: 2183
Job #73 finished at time: 2183
Job #33 arrived at Disk1 at time: 2183
Job #193 arrived at time: 2183
Job #192 arrived at CPU at time: 2197
Job #189 finished at CPU at time: 2197
Job #194 arrived at time: 2197
Job #193 arrived at CPU at time: 2205
Job #33 finished at Disk1 at time: 2205
Job #190 finished at CPU at time: 2205
Job #195 arrived at time: 2205
Job #194 arrived at CPU at time: 2223
Job #33 finished at time: 2223
Job #76 arrived at Disk1 at time: 2223
Job #191 finished at CPU at time: 2223
Job #68 finished at Disk2 at time: 2223
Job #193 finished at CPU at time: 2223
Job #196 arrived at time: 2223
Job #195 arrived at CPU at time: 2232
Job #191 finished at time: 2232
Job #68 finished at time: 2232
Job #69 arrived at Disk2 at time: 2232
Job #192 finished at CPU at time: 2232
Job #197 arrived at time: 2232
Job #196 arrived at CPU at time: 2249
Job #76 finished at Disk1 at time: 2249
Job #194 finished at CPU at time: 2249
Job #198 arrived at time: 2249
Job #197 arrived at CPU at time: 2255
Job #76 finished at time: 2255
Job #80 arrived at Disk1 at time: 2255
Job #199 arrived at time: 2255
Job #198 arrived at CPU at time: 2268
Job #196 finished at CPU at time: 2268
Job #195 finished at CPU at time: 2268
Job #69 finished at Disk2 at time: 2268
Job #197 finished at CPU at time: 2268
Job #200 arrived at time: 2268
Job #199 arrived at CPU at time: 2286
Job #69 finished at time: 2286
Job #26 arrived at Disk2 at time: 2286
Job #197 finished at time: 2286
Job #201 arrived at time: 2286
Job #200 arrived at CPU at time: 2300
Job #80 finished at Disk1 at time: 2300
Job #202 arrived at time: 2300
Job #201 arrived at CPU at time: 2316
Job #80 finished at time: 2316
Job #10 arrived at Disk1 at time: 2316
Job #199 finished at CPU at time: 2316
Job #26 finished at Disk2 at time: 2316
Job #198 finished at CPU at time: 2316
Job #203 arrived at time: 2316
Job #202 arrived at CPU at time: 2325
Job #26 finished at time: 2325
Job #72 arrived at Disk2 at time: 2325
Job #204 arrived at time: 2325
Job #203 arrived at CPU at time: 2343
Job #72 finished at Disk2 at time: 2343
Job #10 finished at Disk1 at time: 2343
Job #202 finished at CPU at time: 2343
Job #205 arrived at time: 2343
Job #204 arrived at CPU at time: 2349
Job #72 finished at time: 2349
Job #27 arrived at Disk2 at time: 2349
Job #10 finished at time: 2349
Job #82 arrived at Disk1 at time: 2349
Job #201 finished at CPU at time: 2349
Job #200 finished at CPU at time: 2349
Job #206 arrived at time: 2349
Job #205 arrived at CPU at time: 2355
Job #201 finished at time: 2355
Job #200 finished at time: 2355
Job #207 arrived at time: 2355
Job #206 arrived at CPU at time: 2366
Job #208 arrived at time: 2366
Job #207 arrived at CPU at time: 2380
Job #82 finished at Disk1 at time: 2380
Job #205 finished at CPU at time: 2380
Job #203 finished at CPU at time: 2380
Job #209 arrived at time: 2380
Job #208 arrived at CPU at time: 2391
Job #82 finished at time: 2391
Job #35 arrived at Disk1 at time: 2391
Job #205 finished at time: 2391
Job #203 finished at time: 2391
Job #204 finished at CPU at time: 2391
Job #27 finished at Disk2 at time: 2391
Job #207 finished at CPU at time: 2391
Job #210 arrived at time: 2391
Job #209 arrived at CPU at time: 2409
Job #27 finished at time: 2409
Job #79 arrived at Disk2 at time: 2409
Job #206 finished at CPU at time: 2409
Job #211 arrived at time: 2409
Job #210 arrived at CPU at time: 2415
Job #206 finished at time: 2415
Job #212 arrived at time: 2415
Job #211 arrived at CPU at time: 2431
Job #35 finished at Disk1 at time: 2431
Job #208 finished at CPU at time: 2431
Job #213 arrived at time: 2431
Job #212 arrived at CPU at time: 2446
Job #35 finished at time: 2446
Job #84 arrived at Disk1 at time: 2446
Job #209 finished at CPU at time: 2446
Job #79 finished at Disk2 at time: 2446
Job #214 arrived at time: 2446
Job #213 arrived at CPU at time: 2456
Job #79 finished at time: 2456
Job #12 arrived at Disk2 at time: 2456
Job #210 finished at CPU at time: 2456
Job #215 arrived at time: 2456
Job #214 arrived at CPU at time: 2464
Job #210 finished at time: 2464
Job #216 arrived at time: 2464
Job #215 arrived at CPU at time: 2474
Job #84 finished at Disk1 at time: 2474
Job #211 finished at CPU at time: 2474
Job #217 arrived at time: 2474
Job #216 arrived at CPU at time: 2480
Job #84 finished at time: 2480
Job #86 arrived at Disk1 at time: 2480
Job #214 finished at CPU at time: 2480
Job #218 arrived at time: 2480
Job #217 arrived at CPU at time: 2496
Job #86 finished at Disk1 at time: 2496
Job #212 finished at CPU at time: 2496
Job #216 finished at CPU at time: 2496
Job #12 finished at Disk2 at time: 2496
Job #219 arrived at time: 2496
Job #218 arrived at CPU at time: 2505
Job #86 finished at time: 2505
Job #38 arrived at Disk1 at time: 2505
Job #212 finished at time: 2505
Job #12 finished at time: 2505
Job #77 arrived at Disk2 at time: 2505
Job #213 finished at CPU at time: 2505
Job #215 finished at CPU at time: 2505
Job #220 arrived at time: 2505
Job #219 arrived at CPU at time: 2510
Job #213 finished at time: 2510
Job #221 arrived at time: 2510
Job #220 arrived at CPU at time: 2518
Job #38 finished at Disk1 at time: 2518
Job #222 arrived at time: 2518
Job #221 arrived at CPU at time: 2523
Job #38 finished at time: 2523
Job #91 arrived at Disk1 at time: 2523
Job #223 arrived at time: 2523
Job #222 arrived at CPU at time: 2538
Job #217 finished at CPU at time: 2538
Job #219 finished at CPU at time: 2538
Job #221 finished at CPU at time: 2538
Job #224 arrived at time: 2538
Job #223 arrived at CPU at time: 2551
Job #220 finished at CPU at time: 2551
Job #218 finished at CPU at time: 2551
Job #91 finished at Disk1 at time: 2551
Job #77 finished at Disk2 at time: 2551
Job #225 arrived at time: 2551
Job #224 arrived at CPU at time: 2566
Job #91 finished at time: 2566
Job #20 arrived at Disk1 at time: 2566
Job #77 finished at time: 2566
Job #81 arrived at Disk2 at time: 2566
Job #222 finished at CPU at time: 2566
Job #223 finished at CPU at time: 2566
Job #226 arrived at time: 2566
Job #225 arrived at CPU at time: 2583
Job #227 arrived at time: 2583
Job #226 arrived at CPU at time: 2593
Job #20 finished at Disk1 at time: 2593
Job #81 finished at Disk2 at time: 2593
Job #224 finished at CPU at time: 2593
Job #228 arrived at time: 2593
Job #227 arrived at CPU at time: 2608
Job #20 finished at time: 2608
Job #93 arrived at Disk1 at time: 2608
Job #81 finished at time: 2608
Job #83 arrived at Disk2 at time: 2608
Job #229 arrived at time: 2608
Job #228 arrived at CPU at time: 2619
Job #226 finished at CPU at time: 2619
Job #93 finished at Disk1 at time: 2619
Job #230 arrived at time: 2619
Job #229 arrived at CPU at time: 2624
Job #93 finished at time: 2624
Job #96 arrived at Disk1 at time: 2624
Job #231 arrived at time: 2624
Job #230 arrived at CPU at time: 2641
Job #225 finished at CPU at time: 2641
Job #228 finished at CPU at time: 2641
Job #227 finished at CPU at time: 2641
Job #232 arrived at time: 2641
Job #231 arrived at CPU at time: 2651
Job #227 finished at time: 2651
Job #83 finished at Disk2 at time: 2651
Job #233 arrived at time: 2651
Job #232 arrived at CPU at time: 2665
Job #83 finished at time: 2665
Job #29 arrived at Disk2 at time: 2665
Job #96 finished at Disk1 at time: 2665
Job #229 finished at CPU at time: 2665
Job #234 arrived at time: 2665
Job #233 arrived at CPU at time: 2678
Job #96 finished at time: 2678
Job #36 arrived at Disk1 at time: 2678
Job #229 finished at time: 2678
Job #235 arrived at time: 2678
Job #234 arrived at CPU at time: 2694
Job #230 finished at CPU at time: 2694
Job #232 finished at CPU at time: 2694
Job #233 finished at CPU at time: 2694
Job #231 finished at CPU at time: 2694
Job #236 arrived at time: 2694
Job #235 arrived at CPU at time: 2712
Job #230 finished at time: 2712
Job #29 finished at Disk2 at time: 2712
Job #36 finished at Disk1 at time: 2712
Job #234 finished at CPU at time: 2712
Job #237 arrived at time: 2712
Job #236 arrived at CPU at time: 2721
Job #29 finished at time: 2721
Job #85 arrived at Disk2 at time: 2721
Job #36 finished at time: 2721
Job #99 arrived at Disk1 at time: 2721
Job #238 arrived at time: 2721
Job #237 arrived at CPU at time: 2728
Job #239 arrived at time: 2728
Job #238 arrived at CPU at time: 2742
Job #235 finished at CPU at time: 2742
Job #236 finished at CPU at time: 2742
Job #99 finished at Disk1 at time: 2742
Job #240 arrived at time: 2742
Job #239 arrived at CPU at time: 2760
Job #236 finished at time: 2760
Job #99 finished at time: 2760
Job #101 arrived at Disk1 at time: 2760
Job #237 finished at CPU at time: 2760
Job #85 finished at Disk2 at time: 2760
Job #241 arrived at time: 2760
Job #240 arrived at CPU at time: 2765
Job #85 finished at time: 2765
Job #32 arrived at Disk2 at time: 2765
Job #242 arrived at time: 2765
Job #241 arrived at CPU at time: 2780
Job #239 finished at CPU at time: 2780
Job #238 finished at CPU at time: 2780
Job #243 arrived at time: 2780
Job #242 arrived at CPU at time: 2796
Job #32 finished at Disk2 at time: 2796
Job #240 finished at CPU at time: 2796
Job #244 arrived at time: 2796
Job #243 arrived at CPU at time: 2806
Job #32 finished at time: 2806
Job #88 arrived at Disk2 at time: 2806
Job #101 finished at Disk1 at time: 2806
Job #245 arrived at time: 2806
Job #244 arrived at CPU at time: 2822
Job #101 finished at time: 2822
Job #21 arrived at Disk1 at time: 2822
Job #241 finished at CPU at time: 2822
Job #246 arrived at time: 2822
Job #245 arrived at CPU at time: 2839
Job #242 finished at CPU at time: 2839
Job #243 finished at CPU at time: 2839
Job #244 finished at CPU at time: 2839
Job #247 arrived at time: 2839
Job #246 arrived at CPU at time: 2845
Job #88 finished at Disk2 at time: 2845
Job #248 arrived at time: 2845
Job #247 arrived at CPU at time: 2850
Job #88 finished at time: 2850
Job #34 arrived at Disk2 at time: 2850
Job #21 finished at Disk1 at time: 2850
Job #249 arrived at time: 2850
Job #248 arrived at CPU at time: 2868
Job #21 finished at time: 2868
Job #102 arrived at Disk1 at time: 2868
Job #250 arrived at time: 2868
Job #249 arrived at CPU at time: 2874
Job #251 arrived at time: 2874
Job #250 arrived at CPU at time: 2880
Job #245 finished at CPU at time: 2880
Job #252 arrived at time: 2880
Job #251 arrived at CPU at time: 2889
Job #246 finished at CPU at time: 2889
Job #253 arrived at time: 2889
Job #252 arrived at CPU at time: 2907
Job #246 finished at time: 2907
Job #247 finished at CPU at time: 2907
Job #34 finished at Disk2 at time: 2907
Job #249 finished at CPU at time: 2907
Job #254 arrived at time: 2907
Job #253 arrived at CPU at time: 2912
Job #34 finished at time: 2912
Job #92 arrived at Disk2 at time: 2912
Job #102 finished at Disk1 at time: 2912
Job #248 finished at CPU at time: 2912
Job #255 arrived at time: 2912
Job #254 arrived at CPU at time: 2921
Job #102 finished at time: 2921
Job #42 arrived at Disk1 at time: 2921
Job #251 finished at CPU at time: 2921
Job #252 finished at CPU at time: 2921
Job #256 arrived at time: 2921
Job #255 arrived at CPU at time: 2937
Job #250 finished at CPU at time: 2937
Job #257 arrived at time: 2937
Job #256 arrived at CPU at time: 2955
Job #250 finished at time: 2955
Job #92 finished at Disk2 at time: 2955
Job #253 finished at CPU at time: 2955
Job #42 finished at Disk1 at time: 2955
Job #255 finished at CPU at time: 2955
Job #258 arrived at time: 2955
Job #257 arrived at CPU at time: 2970
Job #92 finished at time: 2970
Job #94 arrived at Disk2 at time: 2970
Job #42 finished at time: 2970
Job #109 arrived at Disk1 at time: 2970
Job #254 finished at CPU at time: 2970
Job #259 arrived at time: 2970
Job #258 arrived at CPU at time: 2977
Job #254 finished at time: 2977
Job #256 finished at CPU at time: 2977
Job #260 arrived at time: 2977
Job #259 arrived at CPU at time: 2986
Job #261 arrived at time: 2986
Job #260 arrived at CPU at time: 2999
Job #262 arrived at time: 2999
Job #261 arrived at CPU at time: 3007
Job #257 finished at CPU at time: 3007
Job #109 finished at Disk1 at time: 3007
Job #259 finished at CPU at time: 3007
Job #94 finished at Disk2 at time: 3007
Job #263 arrived at time: 3007
Job #262 arrived at CPU at time: 3012
Job #109 finished at time: 3012
Job #22 arrived at Disk1 at time: 3012
Job #94 finished at time: 3012
Job #15 arrived at Disk2 at time: 3012
Job #264 arrived at time: 3012
Job #263 arrived at CPU at time: 3019
Job #258 finished at CPU at time: 3019
Job #260 finished at CPU at time: 3019
Job #265 arrived at time: 3019
Job #264 arrived at CPU at time: 3025
Job #258 finished at time: 3025
Job #266 arrived at time: 3025
Job #265 arrived at CPU at time: 3037
Job #263 finished at CPU at time: 3037
Job #22 finished at Disk1 at time: 3037
Job #267 arrived at time: 3037
Job #266 arrived at CPU at time: 3046
Job #22 finished at time: 3046
Job #110 arrived at Disk1 at time: 3046
Job #261 finished at CPU at time: 3046
Job #268 arrived at time: 3046
Job #267 arrived at CPU at time: 3052
Job #264 finished at CPU at time: 3052
Job #262 finished at CPU at time: 3052
Job #265 finished at CPU at time: 3052
Job #269 arrived at time: 3052
Job #268 arrived at CPU at time: 3066
Job #266 finished at CPU at time: 3066
Job #110 finished at Disk1 at time: 3066
Job #15 finished at Disk2 at time: 3066
Job #270 arrived at time: 3066
Job #269 arrived at CPU at time: 3074
Job #110 finished at time: 3074
Job #113 arrived at Disk1 at time: 3074
Job #15 finished at time: 3074
Job #95 arrived at Disk2 at time: 3074
Job #271 arrived at time: 3074
Job #270 arrived at CPU at time: 3081
Job #267 finished at CPU at time: 3081
Job #268 finished at CPU at time: 3081
Job #272 arrived at time: 3081
Job #271 arrived at CPU at time: 3095
Job #269 finished at CPU at time: 3095
Job #273 arrived at time: 3095
Job #272 arrived at CPU at time: 3100
Job #274 arrived at time: 3100
Job #273 arrived at CPU at time: 3112
Job #95 finished at Disk2 at time: 3112
Job #270 finished at CPU at time: 3112
Job #113 finished at Disk1 at time: 3112
Job #275 arrived at time: 3112
Job #274 arrived at CPU at time: 3117
Job #95 finished at time: 3117
Job #98 arrived at Disk2 at time: 3117
Job #113 finished at time: 3117
Job #46 arrived at Disk1 at time: 3117
Job #276 arrived at time: 3117
Job #275 arrived at CPU at time: 3134
Job #272 finished at CPU at time: 3134
Job #46 finished at Disk1 at time: 3134
Job #277 arrived at time: 3134
Job #276 arrived at CPU at time: 3150
Job #46 finished at time: 3150
Job #47 arrived at Disk1 at time: 3150
Job #271 finished at CPU at time: 3150
Job #274 finished at CPU at time: 3150
Job #273 finished at CPU at time: 3150
Job #278 arrived at time: 3150
Job #277 arrived at CPU at time: 3160
Job #274 finished at time: 3160
Job #273 finished at time: 3160
Job #275 finished at CPU at time: 3160
Job #279 arrived at time: 3160
Job #278 arrived at CPU at time: 3166
Job #276 finished at CPU at time: 3166
Job #280 arrived at time: 3166
Job #279 arrived at CPU at time: 3172
Job #98 finished at Disk2 at time: 3172
Job #281 arrived at time: 3172
Job #280 arrived at CPU at time: 3186
Job #98 finished at time: 3186
Job #37 arrived at Disk2 at time: 3186
Job #282 arrived at time: 3186
Job #281 arrived at CPU at time: 3195
Job #47 finished at Disk1 at time: 3195
Job #277 finished at CPU at time: 3195
Job #283 arrived at time: 3195
Job #282 arrived at CPU at time: 3213
Job #47 finished at time: 3213
Job #115 arrived at Disk1 at time: 3213
Job #277 finished at time: 3213
Job #278 finished at CPU at time: 3213
Job #279 finished at CPU at time: 3213
Job #37 finished at Disk2 at time: 3213
Job #284 arrived at time: 3213
Job #283 arrived at CPU at time: 3226
Job #37 finished at time: 3226
Job #105 arrived at Disk2 at time: 3226
Job #280 finished at CPU at time: 3226
Job #285 arrived at time: 3226
Job #284 arrived at CPU at time: 3238
Job #281 finished at CPU at time: 3238
Job #115 finished at Disk1 at time: 3238
Job #286 arrived at time: 3238
Job #285 arrived at CPU at time: 3248
Job #115 finished at time: 3248
Job #118 arrived at Disk1 at time: 3248
Job #287 arrived at time: 3248
Job #286 arrived at CPU at time: 3256
Job #284 finished at CPU at time: 3256
Job #288 arrived at time: 3256
Job #287 arrived at CPU at time: 3274
Job #282 finished at CPU at time: 3274
Job #105 finished at Disk2 at time: 3274
Job #283 finished at CPU at time: 3274
Job #286 finished at CPU at time: 3274
Job #289 arrived at time: 3274
Job #288 arrived at CPU at time: 3286
Job #105 finished at time: 3286
Job #107 arrived at Disk2 at time: 3286
Job #290 arrived at time: 3286
Job #289 arrived at CPU at time: 3292
Job #118 finished at Disk1 at time: 3292
Job #285 finished at CPU at time: 3292
Job #287 finished at CPU at time: 3292
Job #291 arrived at time: 3292
Job #290 arrived at CPU at time: 3298
Job #118 finished at time: 3298
Job #120 arrived at Disk1 at time: 3298
Job #292 arrived at time: 3298
Job #291 arrived at CPU at time: 3312
Job #107 finished at Disk2 at time: 3312
Job #290 finished at CPU at time: 3312
Job #293 arrived at time: 3312
Job #292 arrived at CPU at time: 3321
Job #107 finished at time: 3321
Job #39 arrived at Disk2 at time: 3321
Job #288 finished at CPU at time: 3321
Job #289 finished at CPU at time: 3321
Job #294 arrived at time: 3321
Job #293 arrived at CPU at time: 3330
Job #291 finished at CPU at time: 3330
Job #295 arrived at time: 3330
Job #294 arrived at CPU at time: 3335
Job #120 finished at Disk1 at time: 3335
Job #296 arrived at time: 3335
Job #295 arrived at CPU at time: 3348
Job #120 finished at time: 3348
Job #4 arrived at Disk1 at time: 3348
Job #292 finished at CPU at time: 3348
Job #293 finished at CPU at time: 3348
Job #297 arrived at time: 3348
Job #296 arrived at CPU at time: 3362
Job #292 finished at time: 3362
Job #293 finished at time: 3362
Job #39 finished at Disk2 at time: 3362
Job #294 finished at CPU at time: 3362
Job #298 arrived at time: 3362
Job #297 arrived at CPU at time: 3367
Job #39 finished at time: 3367
Job #108 arrived at Disk2 at time: 3367
Job #299 arrived at time: 3367
Job #298 arrived at CPU at time: 3373
Job #300 arrived at time: 3373
Job #299 arrived at CPU at time: 3380
Job #296 finished at CPU at time: 3380
Job #4 finished at Disk1 at time: 3380
Job #301 arrived at time: 3380
Job #300 arrived at CPU at time: 3385
Job #4 finished at time: 3385
Job #123 arrived at Disk1 at time: 3385
Job #295 finished at CPU at time: 3385
Job #302 arrived at time: 3385
Job #301 arrived at CPU at time: 3391
Job #298 finished at CPU at time: 3391
Job #303 arrived at time: 3391
Job #302 arrived at CPU at time: 3407
Job #299 finished at CPU at time: 3407
Job #108 finished at Disk2 at time: 3407
Job #297 finished at CPU at time: 3407
Job #301 finished at CPU at time: 3407
Job #304 arrived at time: 3407
Job #303 arrived at CPU at time: 3419
Job #299 finished at time: 3419
Job #108 finished at time: 3419
Job #2 arrived at Disk2 at time: 3419
Job #123 finished at Disk1 at time: 3419
Job #305 arrived at time: 3419
Job #304 arrived at CPU at time: 3426
Job #123 finished at time: 3426
Job #124 arrived at Disk1 at time: 3426
Job #300 finished at CPU at time: 3426
Job #306 arrived at time: 3426
Job #305 arrived at CPU at time: 3434
Job #303 finished at CPU at time: 3434
Job #307 arrived at time: 3434
Job #306 arrived at CPU at time: 3449
Job #302 finished at CPU at time: 3449
Job #2 finished at Disk2 at time: 3449
Job #308 arrived at time: 3449
Job #307 arrived at CPU at time: 3466
Job #2 finished at time: 3466
Job #111 arrived at Disk2 at time: 3466
Job #124 finished at Disk1 at time: 3466
Job #304 finished at CPU at time: 3466
Job #306 finished at CPU at time: 3466
Job #309 arrived at time: 3466
Job #308 arrived at CPU at time: 3481
Job #124 finished at time: 3481
Job #51 arrived at Disk1 at time: 3481
Job #306 finished at time: 3481
Job #305 finished at CPU at time: 3481
Job #310 arrived at time: 3481
Job #309 arrived at CPU at time: 3488
Job #111 finished at Disk2 at time: 3488
Job #311 arrived at time: 3488
Job #310 arrived at CPU at time: 3498
Job #111 finished at time: 3498
Job #114 arrived at Disk2 at time: 3498
Job #307 finished at CPU at time: 3498
Job #312 arrived at time: 3498
Job #311 arrived at CPU at time: 3504
Job #307 finished at time: 3504
Job #313 arrived at time: 3504
Job #312 arrived at CPU at time: 3513
Job #308 finished at CPU at time: 3513
Job #51 finished at Disk1 at time: 3513
Job #310 finished at CPU at time: 3513
Job #314 arrived at time: 3513
Job #313 arrived at CPU at time: 3527
Job #308 finished at time: 3527
Job #51 finished at time: 3527
Job #11 arrived at Disk1 at time: 3527
Job #114 finished at Disk2 at time: 3527
Job #311 finished at CPU at time: 3527
Job #309 finished at CPU at time: 3527
Job #315 arrived at time: 3527
Job #314 arrived at CPU at time: 3541
Job #114 finished at time: 3541
Job #41 arrived at Disk2 at time: 3541
Job #309 finished at time: 3541
Job #316 arrived at time: 3541
Job #315 arrived at CPU at time: 3548
Job #313 finished at CPU at time: 3548
Job #317 arrived at time: 3548
Job #316 arrived at CPU at time: 3566
Job #312 finished at CPU at time: 3566
Job #314 finished at CPU at time: 3566
Job #11 finished at Disk1 at time: 3566
Job #318 arrived at time: 3566
Job #317 arrived at CPU at time: 3575
Job #314 finished at time: 3575
Job #11 finished at time: 3575
Job #128 arrived at Disk1 at time: 3575
Job #319 arrived at time: 3575
Job #318 arrived at CPU at time: 3584
Job #320 arrived at time: 3584
Job #319 arrived at CPU at time: 3589
Job #41 finished at Disk2 at time: 3589
Job #316 finished at CPU at time: 3589
Job #321 arrived at time: 3589
Job #320 arrived at CPU at time: 3605
Job #41 finished at time: 3605
Job #117 arrived at Disk2 at time: 3605
Job #315 finished at CPU at time: 3605
Job #128 finished at Disk1 at time: 3605
Job #318 finished at CPU at time: 3605
Job #322 arrived at time: 3605
Job #321 arrived at CPU at time: 3610
Job #128 finished at time: 3610
Job #50 arrived at Disk1 at time: 3610
Job #317 finished at CPU at time: 3610
Job #323 arrived at time: 3610
Job #322 arrived at CPU at time: 3619
Job #319 finished at CPU at time: 3619
Job #324 arrived at time: 3619
Job #323 arrived at CPU at time: 3627
Job #117 finished at Disk2 at time: 3627
Job #50 finished at Disk1 at time: 3627
Job #325 arrived at time: 3627
Job #324 arrived at CPU at time: 3637
Job #117 finished at time: 3637
Job #119 arrived at Disk2 at time: 3637
Job #50 finished at time: 3637
Job #130 arrived at Disk1 at time: 3637
Job #326 arrived at time: 3637
Job #325 arrived at CPU at time: 3655
Job #321 finished at CPU at time: 3655
Job #320 finished at CPU at time: 3655
Job #324 finished at CPU at time: 3655
Job #323 finished at CPU at time: 3655
Job #119 finished at Disk2 at time: 3655
Job #327 arrived at time: 3655
Job #326 arrived at CPU at time: 3664
Job #119 finished at time: 3664
Job #16 arrived at Disk2 at time: 3664
Job #322 finished at CPU at time: 3664
Job #328 arrived at time: 3664
Job #327 arrived at CPU at time: 3671
Job #325 finished at CPU at time: 3671
Job #329 arrived at time: 3671
Job #328 arrived at CPU at time: 3676
Job #130 finished at Disk1 at time: 3676
Job #330 arrived at time: 3676
Job #329 arrived at CPU at time: 3682
Job #130 finished at time: 3682
Job #133 arrived at Disk1 at time: 3682
Job #331 arrived at time: 3682
Job #330 arrived at CPU at time: 3700
Job #332 arrived at time: 3700
Job #331 arrived at CPU at time: 3713
Job #326 finished at CPU at time: 3713
Job #133 finished at Disk1 at time: 3713
Job #327 finished at CPU at time: 3713
Job #328 finished at CPU at time: 3713
Job #329 finished at CPU at time: 3713
Job #16 finished at Disk2 at time: 3713
Job #330 finished at CPU at time: 3713
Job #333 arrived at time: 3713
Job #332 arrived at CPU at time: 3724
Job #133 finished at time: 3724
Job #25 arrived at Disk1 at time: 3724
Job #16 finished at time: 3724
Job #121 arrived at Disk2 at time: 3724
Job #334 arrived at time: 3724
Job #333 arrived at CPU at time: 3742
Job #335 arrived at time: 3742
Job #334 arrived at CPU at time: 3752
Job #331 finished at CPU at time: 3752
Job #332 finished at CPU at time: 3752
Job #336 arrived at time: 3752
Job #335 arrived at CPU at time: 3760
Job #331 finished at time: 3760
Job #121 finished at Disk2 at time: 3760
Job #25 finished at Disk1 at time: 3760
Job #337 arrived at time: 3760
Job #336 arrived at CPU at time: 3775
Job #121 finished at time: 3775
Job #44 arrived at Disk2 at time: 3775
Job #25 finished at time: 3775
Job #136 arrived at Disk1 at time: 3775
Job #333 finished at CPU at time: 3775
Job #334 finished at CPU at time: 3775
Job #338 arrived at time: 3775
Job #337 arrived at CPU at time: 3792
Job #333 finished at time: 3792
Job #335 finished at CPU at time: 3792
Job #336 finished at CPU at time: 3792
Job #339 arrived at time: 3792
Job #338 arrived at CPU at time: 3799
Job #44 finished at Disk2 at time: 3799
Job #340 arrived at time: 3799
Job #339 arrived at CPU at time: 3806
Job #44 finished at time: 3806
Job #126 arrived at Disk2 at time: 3806
Job #136 finished at Disk1 at time: 3806
Job #341 arrived at time: 3806
Job #340 arrived at CPU at time: 3818
Job #136 finished at time: 3818
Job #54 arrived at Disk1 at time: 3818
Job #342 arrived at time: 3818
Job #341 arrived at CPU at time: 3835
Job #339 finished at CPU at time: 3835
Job #337 finished at CPU at time: 3835
Job #338 finished at CPU at time: 3835
Job #126 finished at Disk2 at time: 3835
Job #343 arrived at time: 3835
Job #342 arrived at CPU at time: 3844
Job #126 finished at time: 3844
Job #45 arrived at Disk2 at time: 3844
Job #344 arrived at time: 3844
Job #343 arrived at CPU at time: 3852
Job #341 finished at CPU at time: 3852
Job #345 arrived at time: 3852
Job #344 arrived at CPU at time: 3863
Job #54 finished at Disk1 at time: 3863
Job #340 finished at CPU at time: 3863
Job #346 arrived at time: 3863
Job #345 arrived at CPU at time: 3868
Job #54 finished at time: 3868
Job #139 arrived at Disk1 at time: 3868
Job #45 finished at Disk2 at time: 3868
Job #347 arrived at time: 3868
Job #346 arrived at CPU at time: 3877
Job #45 finished at time: 3877
Job #127 arrived at Disk2 at time: 3877
Job #348 arrived at time: 3877
Job #347 arrived at CPU at time: 3889
Job #343 finished at CPU at time: 3889
Job #345 finished at CPU at time: 3889
Job #342 finished at CPU at time: 3889
Job #139 finished at Disk1 at time: 3889
Job #349 arrived at time: 3889
Job #348 arrived at CPU at time: 3901
Job #342 finished at time: 3901
Job #139 finished at time: 3901
Job #55 arrived at Disk1 at time: 3901
Job #346 finished at CPU at time: 3901
Job #350 arrived at time: 3901
Job #349 arrived at CPU at time: 3914
Job #344 finished at CPU at time: 3914
Job #55 finished at Disk1 at time: 3914
Job #351 arrived at time: 3914
Job #350 arrived at CPU at time: 3923
Job #55 finished at time: 3923
Job #144 arrived at Disk1 at time: 3923
Job #127 finished at Disk2 at time: 3923
Job #352 arrived at time: 3923
Job #351 arrived at CPU at time: 3931
Job #127 finished at time: 3931
Job #129 arrived at Disk2 at time: 3931
Job #353 arrived at time: 3931
Job #352 arrived at CPU at time: 3941
Job #347 finished at CPU at time: 3941
Job #354 arrived at time: 3941
Job #353 arrived at CPU at time: 3954
Job #348 finished at CPU at time: 3954
Job #351 finished at CPU at time: 3954
Job #350 finished at CPU at time: 3954
Job #349 finished at CPU at time: 3954
Job #355 arrived at time: 3954
Job #354 arrived at CPU at time: 3963
Job #351 finished at time: 3963
Job #352 finished at CPU at time: 3963
Job #144 finished at Disk1 at time: 3963
Job #356 arrived at time: 3963
Job #355 arrived at CPU at time: 3981
Job #144 finished at time: 3981
Job #5 arrived at Disk1 at time: 3981
Job #129 finished at Disk2 at time: 3981
Job #357 arrived at time: 3981
Job #356 arrived at CPU at time: 3990
Job #129 finished at time: 3990
Job #19 arrived at Disk2 at time: 3990
Job #358 arrived at time: 3990
Job #357 arrived at CPU at time: 4005
Job #353 finished at CPU at time: 4005
Job #354 finished at CPU at time: 4005
Job #355 finished at CPU at time: 4005
Job #359 arrived at time: 4005
Job #358 arrived at CPU at time: 4011
Job #355 finished at time: 4011
Job #356 finished at CPU at time: 4011
Job #5 finished at Disk1 at time: 4011
Job #360 arrived at time: 4011
Job #359 arrived at CPU at time: 4026
Job #5 finished at time: 4026
Job #146 arrived at Disk1 at time: 4026
Job #19 finished at Disk2 at time: 4026
Job #361 arrived at time: 4026
Job #360 arrived at CPU at time: 4037
Job #19 finished at time: 4037
Job #131 arrived at Disk2 at time: 4037
Job #357 finished at CPU at time: 4037
Job #362 arrived at time: 4037
Job #361 arrived at CPU at time: 4046
Job #357 finished at time: 4046
Job #146 finished at Disk1 at time: 4046
Job #363 arrived at time: 4046
Job #362 arrived at CPU at time: 4061
Job #146 finished at time: 4061
Job #148 arrived at Disk1 at time: 4061
Job #358 finished at CPU at time: 4061
Job #359 finished at CPU at time: 4061
Job #364 arrived at time: 4061
Job #363 arrived at CPU at time: 4075
Job #131 finished at Disk2 at time: 4075
Job #360 finished at CPU at time: 4075
Job #361 finished at CPU at time: 4075
Job #365 arrived at time: 4075
Job #364 arrived at CPU at time: 4085
Job #131 finished at time: 4085
Job #49 arrived at Disk2 at time: 4085
Job #366 arrived at time: 4085
Job #365 arrived at CPU at time: 4099
Job #363 finished at CPU at time: 4099
Job #362 finished at CPU at time: 4099
Job #148 finished at Disk1 at time: 4099
Job #367 arrived at time: 4099
Job #366 arrived at CPU at time: 4111
Job #148 finished at time: 4111
Job #59 arrived at Disk1 at time: 4111
Job #364 finished at CPU at time: 4111
Job #49 finished at Disk2 at time: 4111
Job #368 arrived at time: 4111
Job #367 arrived at CPU at time: 4119
Job #49 finished at time: 4119
Job #134 arrived at Disk2 at time: 4119
Job #369 arrived at time: 4119
Job #368 arrived at CPU at time: 4133
Job #370 arrived at time: 4133
Job #369 arrived at CPU at time: 4147
Job #365 finished at CPU at time: 4147
Job #366 finished at CPU at time: 4147
Job #371 arrived at time: 4147
Job #370 arrived at CPU at time: 4157
Job #59 finished at Disk1 at time: 4157
Job #367 finished at CPU at time: 4157
Job #368 finished at CPU at time: 4157
Job #372 arrived at time: 4157
Job #371 arrived at CPU at time: 4163
Job #59 finished at time: 4163
Job #60 arrived at Disk1 at time: 4163
Job #367 finished at time: 4163
Job #373 arrived at time: 4163
Job #372 arrived at CPU at time: 4178
Job #134 finished at Disk2 at time: 4178
Job #369 finished at CPU at time: 4178
Job #374 arrived at time: 4178
Job #373 arrived at CPU at time: 4186
Job #134 finished at time: 4186
Job #53 arrived at Disk2 at time: 4186
Job #370 finished at CPU at time: 4186
Job #375 arrived at time: 4186
Job #374 arrived at CPU at time: 4192
Job #60 finished at Disk1 at time: 4192
Job #376 arrived at time: 4192
Job #375 arrived at CPU at time: 4205
Job #60 finished at time: 4205
Job #150 arrived at Disk1 at time: 4205
Job #373 finished at CPU at time: 4205
Job #372 finished at CPU at time: 4205
Job #377 arrived at time: 4205
Job #376 arrived at CPU at time: 4210
Job #373 finished at time: 4210
Job #371 finished at CPU at time: 4210
Job #378 arrived at time: 4210
Job #377 arrived at CPU at time: 4215
Job #379 arrived at time: 4215
Job #378 arrived at CPU at time: 4220
Job #53 finished at Disk2 at time: 4220
Job #380 arrived at time: 4220
Job #379 arrived at CPU at time: 4231
Job #53 finished at time: 4231
Job #140 arrived at Disk2 at time: 4231
Job #374 finished at CPU at time: 4231
Job #375 finished at CPU at time: 4231
Job #381 arrived at time: 4231
Job #380 arrived at CPU at time: 4239
Job #375 finished at time: 4239
Job #377 finished at CPU at time: 4239
Job #382 arrived at time: 4239
Job #381 arrived at CPU at time: 4256
Job #150 finished at Disk1 at time: 4256
Job #378 finished at CPU at time: 4256
Job #376 finished at CPU at time: 4256
Job #379 finished at CPU at time: 4256
Job #383 arrived at time: 4256
Job #382 arrived at CPU at time: 4264
Job #150 finished at time: 4264
Job #152 arrived at Disk1 at time: 4264
Job #379 finished at time: 4264
Job #140 finished at Disk2 at time: 4264
Job #384 arrived at time: 4264
Job #383 arrived at CPU at time: 4273
Job #140 finished at time: 4273
Job #141 arrived at Disk2 at time: 4273
Job #380 finished at CPU at time: 4273
Job #385 arrived at time: 4273
Job #384 arrived at CPU at time: 4282
Job #152 finished at Disk1 at time: 4282
Job #382 finished at CPU at time: 4282
Job #386 arrived at time: 4282
Job #385 arrived at CPU at time: 4288
Job #152 finished at time: 4288
Job #28 arrived at Disk1 at time: 4288
Job #382 finished at time: 4288
Job #383 finished at CPU at time: 4288
Job #381 finished at CPU at time: 4288
Job #141 finished at Disk2 at time: 4288
Job #387 arrived at time: 4288
Job #386 arrived at CPU at time: 4298
Job #141 finished at time: 4298
Job #143 arrived at Disk2 at time: 4298
Job #388 arrived at time: 4298
Job #387 arrived at CPU at time: 4312
Job #389 arrived at time: 4312
Job #388 arrived at CPU at time: 4326
Job #384 finished at CPU at time: 4326
Job #28 finished at Disk1 at time: 4326
Job #143 finished at Disk2 at time: 4326
Job #390 arrived at time: 4326
Job #389 arrived at CPU at time: 4341
Job #28 finished at time: 4341
Job #158 arrived at Disk1 at time: 4341
Job #143 finished at time: 4341
Job #145 arrived at Disk2 at time: 4341
Job #385 finished at CPU at time: 4341
Job #386 finished at CPU at time: 4341
Job #391 arrived at time: 4341
Job #390 arrived at CPU at time: 4351
Job #387 finished at CPU at time: 4351
Job #388 finished at CPU at time: 4351
Job #392 arrived at time: 4351
Job #391 arrived at CPU at time: 4360
Job #388 finished at time: 4360
Job #158 finished at Disk1 at time: 4360
Job #389 finished at CPU at time: 4360
Job #393 arrived at time: 4360
Job #392 arrived at CPU at time: 4372
Job #158 finished at time: 4372
Job #62 arrived at Disk1 at time: 4372
Job #389 finished at time: 4372
Job #394 arrived at time: 4372
Job #393 arrived at CPU at time: 4378
Job #395 arrived at time: 4378
Job #394 arrived at CPU at time: 4396
Job #62 finished at Disk1 at time: 4396
Job #391 finished at CPU at time: 4396
Job #390 finished at CPU at time: 4396
Job #145 finished at Disk2 at time: 4396
Job #396 arrived at time: 4396
Job #395 arrived at CPU at time: 4401
Job #62 finished at time: 4401
Job #159 arrived at Disk1 at time: 4401
Job #145 finished at time: 4401
Job #7 arrived at Disk2 at time: 4401
Job #392 finished at CPU at time: 4401
Job #397 arrived at time: 4401
Job #396 arrived at CPU at time: 4406
Job #393 finished at CPU at time: 4406
Job #398 arrived at time: 4406
Job #397 arrived at CPU at time: 4420
Job #394 finished at CPU at time: 4420
Job #399 arrived at time: 4420
Job #398 arrived at CPU at time: 4434
Job #396 finished at CPU at time: 4434
Job #400 arrived at time: 4434
Job #399 arrived at CPU at time: 4449
Job #7 finished at Disk2 at time: 4449
Job #395 finished at CPU at time: 4449
Job #159 finished at Disk1 at time: 4449
Job #397 finished at CPU at time: 4449
Job #401 arrived at time: 4449
Job #400 arrived at CPU at time: 4465
Job #7 finished at time: 4465
Job #52 arrived at Disk2 at time: 4465
Job #159 finished at time: 4465
Job #30 arrived at Disk1 at time: 4465
Job #402 arrived at time: 4465
Job #401 arrived at CPU at time: 4478
Job #398 finished at CPU at time: 4478
Job #403 arrived at time: 4478
Job #402 arrived at CPU at time: 4492
Job #398 finished at time: 4492
Job #399 finished at CPU at time: 4492
Job #30 finished at Disk1 at time: 4492
Job #404 arrived at time: 4492
Job #403 arrived at CPU at time: 4498
Job #30 finished at time: 4498
Job #163 arrived at Disk1 at time: 4498
Job #405 arrived at time: 4498
Job #404 arrived at CPU at time: 4503
Job #400 finished at CPU at time: 4503
Job #52 finished at Disk2 at time: 4503
Job #406 arrived at time: 4503
Job #405 arrived at CPU at time: 4510
Job #52 finished at time: 4510
Job #151 arrived at Disk2 at time: 4510
Job #401 finished at CPU at time: 4510
Job #407 arrived at time: 4510
Job #406 arrived at CPU at time: 4523
Job #403 finished at CPU at time: 4523
Job #163 finished at Disk1 at time: 4523
Job #408 arrived at time: 4523
Job #407 arrived at CPU at time: 4537
Job #163 finished at time: 4537
Job #65 arrived at Disk1 at time: 4537
Job #402 finished at CPU at time: 4537
Job #151 finished at Disk2 at time: 4537
Job #409 arrived at time: 4537
Job #408 arrived at CPU at time: 4548
Job #151 finished at time: 4548
Job #149 arrived at Disk2 at time: 4548
Job #406 finished at CPU at time: 4548
Job #404 finished at CPU at time: 4548
Job #405 finished at CPU at time: 4548
Job #410 arrived at time: 4548
Job #409 arrived at CPU at time: 4566
Job #149 finished at Disk2 at time: 4566
Job #411 arrived at time: 4566
Job #410 arrived at CPU at time: 4582
Job #149 finished at time: 4582
Job #56 arrived at Disk2 at time: 4582
Job #407 finished at CPU at time: 4582
Job #65 finished at Disk1 at time: 4582
Job #412 arrived at time: 4582
Job #411 arrived at CPU at time: 4591
Job #65 finished at time: 4591
Job #167 arrived at Disk1 at time: 4591
Job #409 finished at CPU at time: 4591
Job #408 finished at CPU at time: 4591
Job #413 arrived at time: 4591
Job #412 arrived at CPU at time: 4600
Job #414 arrived at time: 4600
Job #413 arrived at CPU at time: 4612
Job #410 finished at CPU at time: 4612
Job #415 arrived at time: 4612
Job #414 arrived at CPU at time: 4618
Job #412 finished at CPU at time: 4618
Job #416 arrived at time: 4618
Job #415 arrived at CPU at time: 4625
Job #167 finished at Disk1 at time: 4625
Job #56 finished at Disk2 at time: 4625
Job #411 finished at CPU at time: 4625
Job #417 arrived at time: 4625
Job #416 arrived at CPU at time: 4642
Job #167 finished at time: 4642
Job #165 arrived at Disk1 at time: 4642
Job #56 finished at time: 4642
Job #157 arrived at Disk2 at time: 4642
Job #411 finished at time: 4642
Job #414 finished at CPU at time: 4642
Job #418 arrived at time: 4642
Job #417 arrived at CPU at time: 4647
Job #419 arrived at time: 4647
Job #418 arrived at CPU at time: 4662
Job #415 finished at CPU at time: 4662
Job #413 finished at CPU at time: 4662
Job #420 arrived at time: 4662
Job #419 arrived at CPU at time: 4680
Job #157 finished at Disk2 at time: 4680
Job #165 finished at Disk1 at time: 4680
Job #416 finished at CPU at time: 4680
Job #421 arrived at time: 4680
Job #420 arrived at CPU at time: 4686
Job #157 finished at time: 4686
Job #156 arrived at Disk2 at time: 4686
Job #165 finished at time: 4686
Job #66 arrived at Disk1 at time: 4686
Job #418 finished at CPU at time: 4686
Job #422 arrived at time: 4686
Job #421 arrived at CPU at time: 4696
Job #417 finished at CPU at time: 4696
Job #423 arrived at time: 4696
Job #422 arrived at CPU at time: 4713
Job #421 finished at CPU at time: 4713
Job #424 arrived at time: 4713
Job #423 arrived at CPU at time: 4729
Job #419 finished at CPU at time: 4729
Job #156 finished at Disk2 at time: 4729
Job #66 finished at Disk1 at time: 4729
Job #422 finished at CPU at time: 4729
Job #420 finished at CPU at time: 4729
Job #425 arrived at time: 4729
Job #424 arrived at CPU at time: 4745
Job #156 finished at time: 4745
Job #57 arrived at Disk2 at time: 4745
Job #66 finished at time: 4745
Job #171 arrived at Disk1 at time: 4745
Job #422 finished at time: 4745
Job #426 arrived at time: 4745
Job #425 arrived at CPU at time: 4762
Job #171 finished at Disk1 at time: 4762
Job #423 finished at CPU at time: 4762
Job #57 finished at Disk2 at time: 4762
Job #427 arrived at time: 4762
Job #426 arrived at CPU at time: 4773
Job #171 finished at time: 4773
Job #172 arrived at Disk1 at time: 4773
Job #57 finished at time: 4773
Job #58 arrived at Disk2 at time: 4773
Job #424 finished at CPU at time: 4773
Job #428 arrived at time: 4773
Job #427 arrived at CPU at time: 4785
Job #429 arrived at time: 4785
Job #428 arrived at CPU at time: 4791
Job #430 arrived at time: 4791
Job #429 arrived at CPU at time: 4797
Job #426 finished at CPU at time: 4797
Job #431 arrived at time: 4797
Job #430 arrived at CPU at time: 4812
Job #427 finished at CPU at time: 4812
Job #425 finished at CPU at time: 4812
Job #172 finished at Disk1 at time: 4812
Job #432 arrived at time: 4812
Job #431 arrived at CPU at time: 4827
Job #425 finished at time: 4827
Job #172 finished at time: 4827
Job #174 arrived at Disk1 at time: 4827
Job #429 finished at CPU at time: 4827
Job #428 finished at CPU at time: 4827
Job #58 finished at Disk2 at time: 4827
Job #433 arrived at time: 4827
Job #432 arrived at CPU at time: 4843
Job #58 finished at time: 4843
Job #164 arrived at Disk2 at time: 4843
Job #430 finished at CPU at time: 4843
Job #174 finished at Disk1 at time: 4843
Job #434 arrived at time: 4843
Job #433 arrived at CPU at time: 4848
Job #174 finished at time: 4848
Job #14 arrived at Disk1 at time: 4848
Job #435 arrived at time: 4848
Job #434 arrived at CPU at time: 4865
Job #431 finished at CPU at time: 4865
Job #432 finished at CPU at time: 4865
Job #436 arrived at time: 4865
Job #435 arrived at CPU at time: 4883
Job #431 finished at time: 4883
Job #432 finished at time: 4883
Job #14 finished at Disk1 at time: 4883
Job #164 finished at Disk2 at time: 4883
Job #437 arrived at time: 4883
Job #436 arrived at CPU at time: 4901
Job #14 finished at time: 4901
Job #71 arrived at Disk1 at time: 4901
Job #164 finished at time: 4901
Job #162 arrived at Disk2 at time: 4901
Job #433 finished at CPU at time: 4901
Job #434 finished at CPU at time: 4901
Job #438 arrived at time: 4901
Job #437 arrived at CPU at time: 4916
Job #439 arrived at time: 4916
Job #438 arrived at CPU at time: 4934
Job #71 finished at Disk1 at time: 4934
Job #436 finished at CPU at time: 4934
Job #435 finished at CPU at time: 4934
Job #440 arrived at time: 4934
Job #439 arrived at CPU at time: 4942
Job #71 finished at time: 4942
Job #177 arrived at Disk1 at time: 4942
Job #436 finished at time: 4942
Job #441 arrived at time: 4942
Job #440 arrived at CPU at time: 4954
Job #162 finished at Disk2 at time: 4954
Job #438 finished at CPU at time: 4954
Job #442 arrived at time: 4954
Job #441 arrived at CPU at time: 4961
Job #162 finished at time: 4961
Job #166 arrived at Disk2 at time: 4961
Job #437 finished at CPU at time: 4961
Job #439 finished at CPU at time: 4961
Job #443 arrived at time: 4961
Job #442 arrived at CPU at time: 4976
Job #440 finished at CPU at time: 4976
Job #177 finished at Disk1 at time: 4976
Job #444 arrived at time: 4976
Job #443 arrived at CPU at time: 4994
Job #440 finished at time: 4994
Job #177 finished at time: 4994
Job #180 arrived at Disk1 at time: 4994
Job #445 arrived at time: 4994
Job #444 arrived at CPU at time: 5011
Job #166 finished at Disk2 at time: 5011
Job #441 finished at CPU at time: 5011
Job #180 finished at Disk1 at time: 5011
Job #446 arrived at time: 5011
Job #445 arrived at CPU at time: 5027
Job #166 finished at time: 5027
Job #23 arrived at Disk2 at time: 5027
Job #180 finished at time: 5027
Job #178 arrived at Disk1 at time: 5027
Job #442 finished at CPU at time: 5027
Job #443 finished at CPU at time: 5027
Job #447 arrived at time: 5027
Job #446 arrived at CPU at time: 5038
Job #444 finished at CPU at time: 5038
Job #448 arrived at time: 5038
Job #447 arrived at CPU at time: 5055
Job #445 finished at CPU at time: 5055
Job #446 finished at CPU at time: 5055
Job #449 arrived at time: 5055
Job #448 arrived at CPU at time: 5071
Job #178 finished at Disk1 at time: 5071
Job #23 finished at Disk2 at time: 5071
Job #450 arrived at time: 5071
Job #449 arrived at CPU at time: 5076
Job #178 finished at time: 5076
Job #31 arrived at Disk1 at time: 5076
Job #23 finished at time: 5076
Job #169 arrived at Disk2 at time: 5076
Job #451 arrived at time: 5076
Job #450 arrived at CPU at time: 5083
Job #447 finished at CPU at time: 5083
Job #452 arrived at time: 5083
Job #451 arrived at CPU at time: 5098
Job #449 finished at CPU at time: 5098
Job #448 finished at CPU at time: 5098
Job #453 arrived at time: 5098
Job #452 arrived at CPU at time: 5111
Job #169 finished at Disk2 at time: 5111
Job #31 finished at Disk1 at time: 5111
Job #450 finished at CPU at time: 5111
Job #454 arrived at time: 5111
Job #453 arrived at CPU at time: 5117
Job #169 finished at time: 5117
Job #1 arrived at Disk2 at time: 5117
Job #31 finished at time: 5117
Job #183 arrived at Disk1 at time: 5117
Job #450 finished at time: 5117
Job #451 finished at CPU at time: 5117
Job #455 arrived at time: 5117
Job #454 arrived at CPU at time: 5122
Job #456 arrived at time: 5122
Job #455 arrived at CPU at time: 5136
Job #457 arrived at time: 5136
Job #456 arrived at CPU at time: 5146
Job #183 finished at Disk1 at time: 5146
Job #452 finished at CPU at time: 5146
Job #458 arrived at time: 5146
Job #457 arrived at CPU at time: 5157
Job #183 finished at time: 5157
Job #185 arrived at Disk1 at time: 5157
Job #455 finished at CPU at time: 5157
Job #454 finished at CPU at time: 5157
Job #1 finished at Disk2 at time: 5157
Job #453 finished at CPU at time: 5157
Job #459 arrived at time: 5157
Job #458 arrived at CPU at time: 5174
Job #1 finished at time: 5174
Job #170 arrived at Disk2 at time: 5174
Job #460 arrived at time: 5174
Job #459 arrived at CPU at time: 5191
Job #456 finished at CPU at time: 5191
Job #457 finished at CPU at time: 5191
Job #185 finished at Disk1 at time: 5191
Job #170 finished at Disk2 at time: 5191
Job #461 arrived at time: 5191
Job #460 arrived at CPU at time: 5209
Job #185 finished at time: 5209
Job #73 arrived at Disk1 at time: 5209
Job #170 finished at time: 5209
Job #64 arrived at Disk2 at time: 5209
Job #462 arrived at time: 5209
Job #461 arrived at CPU at time: 5218
Job #459 finished at CPU at time: 5218
Job #458 finished at CPU at time: 5218
Job #463 arrived at time: 5218
Job #462 arrived at CPU at time: 5236
Job #458 finished at time: 5236
Job #73 finished at Disk1 at time: 5236
Job #464 arrived at time: 5236
Job #463 arrived at CPU at time: 5242
Job #73 finished at time: 5242
Job #33 arrived at Disk1 at time: 5242
Job #460 finished at CPU at time: 5242
Job #64 finished at Disk2 at time: 5242
Job #465 arrived at time: 5242
Job #464 arrived at CPU at time: 5250
Job #64 finished at time: 5250
Job #173 arrived at Disk2 at time: 5250
Job #462 finished at CPU at time: 5250
Job #466 arrived at time: 5250
Job #465 arrived at CPU at time: 5265
Job #462 finished at time: 5265
Job #461 finished at CPU at time: 5265
Job #467 arrived at time: 5265
Job #466 arrived at CPU at time: 5270
Job #463 finished at CPU at time: 5270
Job #33 finished at Disk1 at time: 5270
Job #468 arrived at time: 5270
Job #467 arrived at CPU at time: 5285
Job #33 finished at time: 5285
Job #189 arrived at Disk1 at time: 5285
Job #464 finished at CPU at time: 5285
Job #173 finished at Disk2 at time: 5285
Job #469 arrived at time: 5285
Job #468 arrived at CPU at time: 5294
Job #173 finished at time: 5294
Job #175 arrived at Disk2 at time: 5294
Job #466 finished at CPU at time: 5294
Job #470 arrived at time: 5294
Job #469 arrived at CPU at time: 5309
Job #465 finished at CPU at time: 5309
Job #467 finished at CPU at time: 5309
Job #189 finished at Disk1 at time: 5309
Job #471 arrived at time: 5309
Job #470 arrived at CPU at time: 5326
Job #189 finished at time: 5326
Job #190 arrived at Disk1 at time: 5326
Job #468 finished at CPU at time: 5326
Job #472 arrived at time: 5326
Job #471 arrived at CPU at time: 5336
Job #473 arrived at time: 5336
Job #472 arrived at CPU at time: 5351
Job #469 finished at CPU at time: 5351
Job #175 finished at Disk2 at time: 5351
Job #474 arrived at time: 5351
Job #473 arrived at CPU at time: 5367
Job #175 finished at time: 5367
Job #176 arrived at Disk2 at time: 5367
Job #190 finished at Disk1 at time: 5367
Job #475 arrived at time: 5367
Job #474 arrived at CPU at time: 5384
Job #190 finished at time: 5384
Job #76 arrived at Disk1 at time: 5384
Job #470 finished at CPU at time: 5384
Job #471 finished at CPU at time: 5384
Job #472 finished at CPU at time: 5384
Job #473 finished at CPU at time: 5384
Job #476 arrived at time: 5384
Job #475 arrived at CPU at time: 5390
Job #471 finished at time: 5390
Job #477 arrived at time: 5390
Job #476 arrived at CPU at time: 5397
Job #478 arrived at time: 5397
Job #477 arrived at CPU at time: 5405
Job #479 arrived at time: 5405
Job #478 arrived at CPU at time: 5415
Job #76 finished at Disk1 at time: 5415
Job #476 finished at CPU at time: 5415
Job #480 arrived at time: 5415
Job #479 arrived at CPU at time: 5428
Job #76 finished at time: 5428
Job #192 arrived at Disk1 at time: 5428
Job #476 finished at time: 5428
Job #176 finished at Disk2 at time: 5428
Job #474 finished at CPU at time: 5428
Job #477 finished at CPU at time: 5428
Job #481 arrived at time: 5428
Job #480 arrived at CPU at time: 5443
Job #176 finished at time: 5443
Job #63 arrived at Disk2 at time: 5443
Job #475 finished at CPU at time: 5443
Job #482 arrived at time: 5443
Job #481 arrived at CPU at time: 5457
Job #478 finished at CPU at time: 5457
Job #479 finished at CPU at time: 5457
Job #483 arrived at time: 5457
Job #482 arrived at CPU at time: 5467
Job #478 finished at time: 5467
Job #479 finished at time: 5467
Job #192 finished at Disk1 at time: 5467
Job #484 arrived at time: 5467
Job #483 arrived at CPU at time: 5477
Job #192 finished at time: 5477
Job #194 arrived at Disk1 at time: 5477
Job #63 finished at Disk2 at time: 5477
Job #485 arrived at time: 5477
Job #484 arrived at CPU at time: 5491
Job #63 finished at time: 5491
Job #24 arrived at Disk2 at time: 5491
Job #480 finished at CPU at time: 5491
Job #482 finished at CPU at time: 5491
Job #486 arrived at time: 5491
Job #485 arrived at CPU at time: 5503
Job #482 finished at time: 5503
Job #481 finished at CPU at time: 5503
Job #487 arrived at time: 5503
Job #486 arrived at CPU at time: 5519
Job #483 finished at CPU at time: 5519
Job #194 finished at Disk1 at time: 5519
Job #484 finished at CPU at time: 5519
Job #488 arrived at time: 5519
Job #487 arrived at CPU at time: 5531
Job #194 finished at time: 5531
Job #80 arrived at Disk1 at time: 5531
Job #24 finished at Disk2 at time: 5531
Job #489 arrived at time: 5531
Job #488 arrived at CPU at time: 5549
Job #24 finished at time: 5549
Job #179 arrived at Disk2 at time: 5549
Job #485 finished at CPU at time: 5549
Job #486 finished at CPU at time: 5549
Job #487 finished at CPU at time: 5549
Job #490 arrived at time: 5549
Job #489 arrived at CPU at time: 5560
Job #485 finished at time: 5560
Job #80 finished at Disk1 at time: 5560
Job #488 finished at CPU at time: 5560
Job #491 arrived at time: 5560
Job #490 arrived at CPU at time: 5566
Job #80 finished at time: 5566
Job #10 arrived at Disk1 at time: 5566
Job #488 finished at time: 5566
Job #492 arrived at time: 5566
Job #491 arrived at CPU at time: 5571
Job #493 arrived at time: 5571
Job #492 arrived at CPU at time: 5589
Job #490 finished at CPU at time: 5589
Job #494 arrived at time: 5589
Job #493 arrived at CPU at time: 5596
Job #489 finished at CPU at time: 5596
Job #10 finished at Disk1 at time: 5596
Job #495 arrived at time: 5596
Job #494 arrived at CPU at time: 5606
Job #10 finished at time: 5606
Job #199 arrived at Disk1 at time: 5606
Job #179 finished at Disk2 at time: 5606
Job #496 arrived at time: 5606
Job #495 arrived at CPU at time: 5611
Job #179 finished at time: 5611
Job #182 arrived at Disk2 at time: 5611
Job #497 arrived at time: 5611
Job #496 arrived at CPU at time: 5617
Job #491 finished at CPU at time: 5617
Job #498 arrived at time: 5617
Job #497 arrived at CPU at time: 5631
Job #199 finished at Disk1 at time: 5631
Job #492 finished at CPU at time: 5631
Job #493 finished at CPU at time: 5631
Job #496 finished at CPU at time: 5631
Job #499 arrived at time: 5631
Job #498 arrived at CPU at time: 5636
Job #199 finished at time: 5636
Job #202 arrived at Disk1 at time: 5636
Job #492 finished at time: 5636
Job #496 finished at time: 5636
Job #494 finished at CPU at time: 5636
Job #500 arrived at time: 5636
Job #499 arrived at CPU at time: 5652
Job #495 finished at CPU at time: 5652
Job #497 finished at CPU at time: 5652
Job #501 arrived at time: 5652
Job #500 arrived at CPU at time: 5660
Job #495 finished at time: 5660
Job #182 finished at Disk2 at time: 5660
Job #502 arrived at time: 5660
Job #501 arrived at CPU at time: 5676
Job #182 finished at time: 5676
Job #184 arrived at Disk2 at time: 5676
Job #202 finished at Disk1 at time: 5676
Job #503 arrived at time: 5676
Job #502 arrived at CPU at time: 5690
Job #202 finished at time: 5690
Job #82 arrived at Disk1 at time: 5690
Job #498 finished at CPU at time: 5690
Job #504 arrived at time: 5690
Job #503 arrived at CPU at time: 5702
Job #499 finished at CPU at time: 5702
Job #500 finished at CPU at time: 5702
Job #505 arrived at time: 5702
Job #504 arrived at CPU at time: 5717
Job #499 finished at time: 5717
Job #82 finished at Disk1 at time: 5717
Job #506 arrived at time: 5717
Job #505 arrived at CPU at time: 5729
Job #82 finished at time: 5729
Job #35 arrived at Disk1 at time: 5729
Job #501 finished at CPU at time: 5729
Job #502 finished at CPU at time: 5729
Job #507 arrived at time: 5729
Job #506 arrived at CPU at time: 5737
Job #502 finished at time: 5737
Job #184 finished at Disk2 at time: 5737
Job #508 arrived at time: 5737
Job #507 arrived at CPU at time: 5753
Job #184 finished at time: 5753
Job #188 arrived at Disk2 at time: 5753
Job #504 finished at CPU at time: 5753
Job #503 finished at CPU at time: 5753
Job #509 arrived at time: 5753
Job #508 arrived at CPU at time: 5763
Job #504 finished at time: 5763
Job #505 finished at CPU at time: 5763
Job #510 arrived at time: 5763
Job #509 arrived at CPU at time: 5768
Job #511 arrived at time: 5768
Job #510 arrived at CPU at time: 5781
Job #35 finished at Disk1 at time: 5781
Job #508 finished at CPU at time: 5781
Job #506 finished at CPU at time: 5781
Job #512 arrived at time: 5781
Job #511 arrived at CPU at time: 5791
Job #35 finished at time: 5791
Job #208 arrived at Disk1 at time: 5791
Job #507 finished at CPU at time: 5791
Job #513 arrived at time: 5791
Job #512 arrived at CPU at time: 5808
Job #509 finished at CPU at time: 5808
Job #188 finished at Disk2 at time: 5808
Job #510 finished at CPU at time: 5808
Job #208 finished at Disk1 at time: 5808
Job #514 arrived at time: 5808
Job #513 arrived at CPU at time: 5820
Job #188 finished at time: 5820
Job #186 arrived at Disk2 at time: 5820
Job #208 finished at time: 5820
Job #84 arrived at Disk1 at time: 5820
Job #515 arrived at time: 5820
Job #514 arrived at CPU at time: 5834
Job #516 arrived at time: 5834
Job #515 arrived at CPU at time: 5842
Job #511 finished at CPU at time: 5842
Job #84 finished at Disk1 at time: 5842
Job #517 arrived at time: 5842
Job #516 arrived at CPU at time: 5860
Job #84 finished at time: 5860
Job #209 arrived at Disk1 at time: 5860
Job #513 finished at CPU at time: 5860
Job #512 finished at CPU at time: 5860
Job #518 arrived at time: 5860
Job #517 arrived at CPU at time: 5874
Job #186 finished at Disk2 at time: 5874
Job #209 finished at Disk1 at time: 5874
Job #514 finished at CPU at time: 5874
Job #519 arrived at time: 5874
Job #518 arrived at CPU at time: 5889
Job #186 finished at time: 5889
Job #68 arrived at Disk2 at time: 5889
Job #209 finished at time: 5889
Job #211 arrived at Disk1 at time: 5889
Job #514 finished at time: 5889
Job #515 finished at CPU at time: 5889
Job #520 arrived at time: 5889
Job #519 arrived at CPU at time: 5902
Job #211 finished at Disk1 at time: 5902
Job #521 arrived at time: 5902
Job #520 arrived at CPU at time: 5920
Job #211 finished at time: 5920
Job #86 arrived at Disk1 at time: 5920
Job #516 finished at CPU at time: 5920
Job #517 finished at CPU at time: 5920
Job #68 finished at Disk2 at time: 5920
Job #518 finished at CPU at time: 5920
Job #522 arrived at time: 5920
Job #521 arrived at CPU at time: 5927
Job #517 finished at time: 5927
Job #68 finished at time: 5927
Job #193 arrived at Disk2 at time: 5927
Job #518 finished at time: 5927
Job #519 finished at CPU at time: 5927
Job #523 arrived at time: 5927
Job #522 arrived at CPU at time: 5934
Job #524 arrived at time: 5934
Job #523 arrived at CPU at time: 5946
Job #525 arrived at time: 5946
Job #524 arrived at CPU at time: 5951
Job #521 finished at CPU at time: 5951
Job #86 finished at Disk1 at time: 5951
Job #526 arrived at time: 5951
Job #525 arrived at CPU at time: 5969
Job #521 finished at time: 5969
Job #86 finished at time: 5969
Job #216 arrived at Disk1 at time: 5969
Job #520 finished at CPU at time: 5969
Job #523 finished at CPU at time: 5969
Job #522 finished at CPU at time: 5969
Job #527 arrived at time: 5969
Job #526 arrived at CPU at time: 5987
Job #520 finished at time: 5987
Job #193 finished at Disk2 at time: 5987
Job #524 finished at CPU at time: 5987
Job #216 finished at Disk1 at time: 5987
Job #528 arrived at time: 5987
Job #527 arrived at CPU at time: 6005
Job #193 finished at time: 6005
Job #69 arrived at Disk2 at time: 6005
Job #216 finished at time: 6005
Job #38 arrived at Disk1 at time: 6005
Job #529 arrived at time: 6005
Job #528 arrived at CPU at time: 6011
Job #530 arrived at time: 6011
Job #529 arrived at CPU at time: 6017
Job #525 finished at CPU at time: 6017
Job #527 finished at CPU at time: 6017
Job #531 arrived at time: 6017
Job #530 arrived at CPU at time: 6031
Job #527 finished at time: 6031
Job #526 finished at CPU at time: 6031
Job #38 finished at Disk1 at time: 6031
Job #532 arrived at time: 6031
Job #531 arrived at CPU at time: 6039
Job #38 finished at time: 6039
Job #91 arrived at Disk1 at time: 6039
Job #528 finished at CPU at time: 6039
Job #69 finished at Disk2 at time: 6039
Job #533 arrived at time: 6039
Job #532 arrived at CPU at time: 6048
Job #69 finished at time: 6048
Job #196 arrived at Disk2 at time: 6048
Job #534 arrived at time: 6048
Job #533 arrived at CPU at time: 6062
Job #529 finished at CPU at time: 6062
Job #530 finished at CPU at time: 6062
Job #91 finished at Disk1 at time: 6062
Job #535 arrived at time: 6062
Job #534 arrived at CPU at time: 6070
Job #91 finished at time: 6070
Job #219 arrived at Disk1 at time: 6070
Job #532 finished at CPU at time: 6070
Job #536 arrived at time: 6070
Job #535 arrived at CPU at time: 6078
Job #537 arrived at time: 6078
Job #536 arrived at CPU at time: 6092
Job #533 finished at CPU at time: 6092
Job #531 finished at CPU at time: 6092
Job #196 finished at Disk2 at time: 6092
Job #538 arrived at time: 6092
Job #537 arrived at CPU at time: 6105
Job #531 finished at time: 6105
Job #196 finished at time: 6105
Job #195 arrived at Disk2 at time: 6105
Job #219 finished at Disk1 at time: 6105
Job #539 arrived at time: 6105
Job #538 arrived at CPU at time: 6120
Job #219 finished at time: 6120
Job #220 arrived at Disk1 at time: 6120
Job #535 finished at CPU at time: 6120
Job #534 finished at CPU at time: 6120
Job #540 arrived at time: 6120
Job #539 arrived at CPU at time: 6133
Job #195 finished at Disk2 at time: 6133
Job #541 arrived at time: 6133
Job #540 arrived at CPU at time: 6139
Job #195 finished at time: 6139
Job #26 arrived at Disk2 at time: 6139
Job #536 finished at CPU at time: 6139
Job #542 arrived at time: 6139
Job #541 arrived at CPU at time: 6151
Job #537 finished at CPU at time: 6151
Job #538 finished at CPU at time: 6151
Job #220 finished at Disk1 at time: 6151
Job #543 arrived at time: 6151
Job #542 arrived at CPU at time: 6166
Job #220 finished at time: 6166
Job #20 arrived at Disk1 at time: 6166
Job #539 finished at CPU at time: 6166
Job #26 finished at Disk2 at time: 6166
Job #540 finished at CPU at time: 6166
Job #544 arrived at time: 6166
Job #543 arrived at CPU at time: 6176
Job #539 finished at time: 6176
Job #26 finished at time: 6176
Job #198 arrived at Disk2 at time: 6176
Job #541 finished at CPU at time: 6176
Job #545 arrived at time: 6176
Job #544 arrived at CPU at time: 6189
Job #20 finished at Disk1 at time: 6189
Job #546 arrived at time: 6189
Job #545 arrived at CPU at time: 6197
Job #20 finished at time: 6197
Job #222 arrived at Disk1 at time: 6197
Job #543 finished at CPU at time: 6197
Job #547 arrived at time: 6197
Job #546 arrived at CPU at time: 6204
Job #544 finished at CPU at time: 6204
Job #548 arrived at time: 6204
Job #547 arrived at CPU at time: 6221
Job #542 finished at CPU at time: 6221
Job #549 arrived at time: 6221
Job #548 arrived at CPU at time: 6233
Job #198 finished at Disk2 at time: 6233
Job #545 finished at CPU at time: 6233
Job #222 finished at Disk1 at time: 6233
Job #550 arrived at time: 6233
Job #549 arrived at CPU at time: 6248
Job #198 finished at time: 6248
Job #72 arrived at Disk2 at time: 6248
Job #222 finished at time: 6248
Job #224 arrived at Disk1 at time: 6248
Job #546 finished at CPU at time: 6248
Job #551 arrived at time: 6248
Job #550 arrived at CPU at time: 6257
Job #546 finished at time: 6257
Job #552 arrived at time: 6257
Job #551 arrived at CPU at time: 6265
Job #547 finished at CPU at time: 6265
Job #553 arrived at time: 6265
Job #552 arrived at CPU at time: 6273
Job #549 finished at CPU at time: 6273
Job #548 finished at CPU at time: 6273
Job #554 arrived at time: 6273
Job #553 arrived at CPU at time: 6288
Job #549 finished at time: 6288
Job #548 finished at time: 6288
Job #551 finished at CPU at time: 6288
Job #224 finished at Disk1 at time: 6288
Job #555 arrived at time: 6288
Job #554 arrived at CPU at time: 6303
Job #224 finished at time: 6303
Job #93 arrived at Disk1 at time: 6303
Job #72 finished at Disk2 at time: 6303
Job #550 finished at CPU at time: 6303
Job #556 arrived at time: 6303
Job #555 arrived at CPU at time: 6318
Job #72 finished at time: 6318
Job #27 arrived at Disk2 at time: 6318
Job #552 finished at CPU at time: 6318
Job #557 arrived at time: 6318
Job #556 arrived at CPU at time: 6333
Job #554 finished at CPU at time: 6333
Job #553 finished at CPU at time: 6333
Job #558 arrived at time: 6333
Job #557 arrived at CPU at time: 6342
Job #93 finished at Disk1 at time: 6342
Job #559 arrived at time: 6342
Job #558 arrived at CPU at time: 6360
Job #93 finished at time: 6360
Job #96 arrived at Disk1 at time: 6360
Job #555 finished at CPU at time: 6360
Job #556 finished at CPU at time: 6360
Job #560 arrived at time: 6360
Job #559 arrived at CPU at time: 6376
Job #27 finished at Disk2 at time: 6376
Job #558 finished at CPU at time: 6376
Job #557 finished at CPU at time: 6376
Job #561 arrived at time: 6376
Job #560 arrived at CPU at time: 6386
Job #27 finished at time: 6386
Job #204 arrived at Disk2 at time: 6386
Job #562 arrived at time: 6386
Job #561 arrived at CPU at time: 6398
Job #96 finished at Disk1 at time: 6398
Job #563 arrived at time: 6398
Job #562 arrived at CPU at time: 6413
Job #96 finished at time: 6413
Job #225 arrived at Disk1 at time: 6413
Job #204 finished at Disk2 at time: 6413
Job #564 arrived at time: 6413
Job #563 arrived at CPU at time: 6424
Job #204 finished at time: 6424
Job #207 arrived at Disk2 at time: 6424
Job #559 finished at CPU at time: 6424
Job #225 finished at Disk1 at time: 6424
Job #562 finished at CPU at time: 6424
Job #565 arrived at time: 6424
Job #564 arrived at CPU at time: 6433
Job #559 finished at time: 6433
Job #225 finished at time: 6433
Job #36 arrived at Disk1 at time: 6433
Job #560 finished at CPU at time: 6433
Job #566 arrived at time: 6433
Job #565 arrived at CPU at time: 6439
Job #560 finished at time: 6439
Job #567 arrived at time: 6439
Job #566 arrived at CPU at time: 6447
Job #561 finished at CPU at time: 6447
Job #568 arrived at time: 6447
Job #567 arrived at CPU at time: 6452
Job #569 arrived at time: 6452
Job #568 arrived at CPU at time: 6469
Job #207 finished at Disk2 at time: 6469
Job #563 finished at CPU at time: 6469
Job #566 finished at CPU at time: 6469
Job #564 finished at CPU at time: 6469
Job #570 arrived at time: 6469
Job #569 arrived at CPU at time: 6487
Job #207 finished at time: 6487
Job #79 arrived at Disk2 at time: 6487
Job #566 finished at time: 6487
Job #565 finished at CPU at time: 6487
Job #36 finished at Disk1 at time: 6487
Job #568 finished at CPU at time: 6487
Job #571 arrived at time: 6487
Job #570 arrived at CPU at time: 6498
Job #36 finished at time: 6498
Job #232 arrived at Disk1 at time: 6498
Job #567 finished at CPU at time: 6498
Job #572 arrived at time: 6498
Job #571 arrived at CPU at time: 6507
Job #573 arrived at time: 6507
Job #572 arrived at CPU at time: 6519
Job #232 finished at Disk1 at time: 6519
Job #569 finished at CPU at time: 6519
Job #574 arrived at time: 6519
Job #573 arrived at CPU at time: 6524
Job #232 finished at time: 6524
Job #231 arrived at Disk1 at time: 6524
Job #570 finished at CPU at time: 6524
Job #575 arrived at time: 6524
Job #574 arrived at CPU at time: 6542
Job #570 finished at time: 6542
Job #573 finished at CPU at time: 6542
Job #231 finished at Disk1 at time: 6542
Job #79 finished at Disk2 at time: 6542
Job #571 finished at CPU at time: 6542
Job #576 arrived at time: 6542
Job #575 arrived at CPU at time: 6560
Job #231 finished at time: 6560
Job #99 arrived at Disk1 at time: 6560
Job #79 finished at time: 6560
Job #12 arrived at Disk2 at time: 6560
Job #571 finished at time: 6560
Job #572 finished at CPU at time: 6560
Job #577 arrived at time: 6560
Job #576 arrived at CPU at time: 6565
Job #578 arrived at time: 6565
Job #577 arrived at CPU at time: 6574
Job #575 finished at CPU at time: 6574
Job #574 finished at CPU at time: 6574
Job #579 arrived at time: 6574
Job #578 arrived at CPU at time: 6588
Job #12 finished at Disk2 at time: 6588
Job #99 finished at Disk1 at time: 6588
Job #580 arrived at time: 6588
Job #579 arrived at CPU at time: 6595
Job #12 finished at time: 6595
Job #214 arrived at Disk2 at time: 6595
Job #99 finished at time: 6595
Job #235 arrived at Disk1 at time: 6595
Job #577 finished at CPU at time: 6595
Job #581 arrived at time: 6595
Job #580 arrived at CPU at time: 6601
Job #582 arrived at time: 6601
Job #581 arrived at CPU at time: 6610
Job #235 finished at Disk1 at time: 6610
Job #576 finished at CPU at time: 6610
Job #583 arrived at time: 6610
Job #582 arrived at CPU at time: 6617
Job #235 finished at time: 6617
Job #101 arrived at Disk1 at time: 6617
Job #576 finished at time: 6617
Job #584 arrived at time: 6617
Job #583 arrived at CPU at time: 6622
Job #578 finished at CPU at time: 6622
Job #585 arrived at time: 6622
Job #584 arrived at CPU at time: 6637
Job #580 finished at CPU at time: 6637
Job #582 finished at CPU at time: 6637
Job #579 finished at CPU at time: 6637
Job #214 finished at Disk2 at time: 6637
Job #586 arrived at time: 6637
Job #585 arrived at CPU at time: 6652
Job #214 finished at time: 6652
Job #77 arrived at Disk2 at time: 6652
Job #581 finished at CPU at time: 6652
Job #101 finished at Disk1 at time: 6652
Job #587 arrived at time: 6652
Job #586 arrived at CPU at time: 6667
Job #581 finished at time: 6667
Job #101 finished at time: 6667
Job #239 arrived at Disk1 at time: 6667
Job #583 finished at CPU at time: 6667
Job #584 finished at CPU at time: 6667
Job #588 arrived at time: 6667
Job #587 arrived at CPU at time: 6679
Job #583 finished at time: 6679
Job #77 finished at Disk2 at time: 6679
Job #589 arrived at time: 6679
Job #588 arrived at CPU at time: 6689
Job #77 finished at time: 6689
Job #215 arrived at Disk2 at time: 6689
Job #590 arrived at time: 6689
Job #589 arrived at CPU at time: 6695
Job #591 arrived at time: 6695
Job #590 arrived at CPU at time: 6710
Job #585 finished at CPU at time: 6710
Job #587 finished at CPU at time: 6710
Job #239 finished at Disk1 at time: 6710
Job #592 arrived at time: 6710
Job #591 arrived at CPU at time: 6720
Job #585 finished at time: 6720
Job #239 finished at time: 6720
Job #21 arrived at Disk1 at time: 6720
Job #586 finished at CPU at time: 6720
Job #593 arrived at time: 6720
Job #592 arrived at CPU at time: 6725
Job #588 finished at CPU at time: 6725
Job #589 finished at CPU at time: 6725
Job #594 arrived at time: 6725
Job #593 arrived at CPU at time: 6730
Job #595 arrived at time: 6730
Job #594 arrived at CPU at time: 6743
Job #215 finished at Disk2 at time: 6743
Job #592 finished at CPU at time: 6743
Job #591 finished at CPU at time: 6743
Job #590 finished at CPU at time: 6743
Job #21 finished at Disk1 at time: 6743
Job #596 arrived at time: 6743
Job #595 arrived at CPU at time: 6755
Job #215 finished at time: 6755
Job #217 arrived at Disk2 at time: 6755
Job #21 finished at time: 6755
Job #241 arrived at Disk1 at time: 6755
